Workbook

Sheet 首頁
A1: 旅外就是神｜V1.3 Excel Final｜今日出賽球員
A2: 投手 | I2: 台灣旅外戰力分布(含台裔)
A3: 姓名 | B3: 今日成績 | I3: MLB | J3: =COUNTIF(總表!$G:$G,"MLB") -> 3
A4: =IFERROR(INDEX(今日戰報!$A$4:$A$200,MATCH(ROWS($A$4:A4),今日戰報!$L$4:$L$200,0)),"") -> 林昱珉 | B4: {=IFERROR(INDEX(今日戰報!$H$4:$H$200,MATCH(ROWS($A$4:A4),今日戰報!$L$4:$L$200,0)),"")} -> 0.2IP，32P，5H，5R，2ER，2K，ERA 6.35，WHIP 2.12(L) | I4: 3A | J4: =COUNTIF(總表!$G:$G,"3A") -> 4
A5: {=IFERROR(INDEX(今日戰報!$A$4:$A$200,MATCH(ROWS($A$4:A5),今日戰報!$L$4:$L$200,0)),"")} -> 陳柏毓 | B5: {=IFERROR(INDEX(今日戰報!$H$4:$H$200,MATCH(ROWS($A$4:A5),今日戰報!$L$4:$L$200,0)),"")} -> 4.0IP，4H，2R，1ER，1HR，4K，2BB，73P,ERA 5.65，WHIP 1.47 (無關勝敗) | I5: 2A | J5: =COUNTIF(總表!$G:$G,"2A") -> 5
A6: {=IFERROR(INDEX(今日戰報!$A$4:$A$200,MATCH(ROWS($A$4:A6),今日戰報!$L$4:$L$200,0)),"")} | B6: {=IFERROR(INDEX(今日戰報!$H$4:$H$200,MATCH(ROWS($A$4:A6),今日戰報!$L$4:$L$200,0)),"")} | I6: 高A | J6: =COUNTIF(總表!$G:$G,"A+") -> 3
A7: {=IFERROR(INDEX(今日戰報!$A$4:$A$200,MATCH(ROWS($A$4:A7),今日戰報!$L$4:$L$200,0)),"")} | B7: {=IFERROR(INDEX(今日戰報!$H$4:$H$200,MATCH(ROWS($A$4:A7),今日戰報!$L$4:$L$200,0)),"")} | I7: 1A | J7: =COUNTIF(總表!$G:$G,"1A") -> 5
A8: {=IFERROR(INDEX(今日戰報!$A$4:$A$200,MATCH(ROWS($A$4:A8),今日戰報!$L$4:$L$200,0)),"")} | B8: {=IFERROR(INDEX(今日戰報!$H$4:$H$200,MATCH(ROWS($A$4:A8),今日戰報!$L$4:$L$200,0)),"")} | I8: Rookie | J8: =COUNTIF(總表!$G:$G,"RK") -> 6
I9: 日職一軍 | J9: =COUNTIF(總表!$G:$G,"日職一軍") -> 2
A10: 野手 | I10: 日職二軍 | J10: =COUNTIF(總表!$G:$G,"日職二軍") -> 11
A11: 姓名 | B11: 今日成績 | I11: 韓職 | J11: =COUNTIF(總表!$G:$G,"韓職一軍")+COUNTIF(總表!$G:$G,"韓職二軍")+COUNTIF(總表!$G:$G,"KBO") -> 1
A12: {=IFERROR(INDEX(今日戰報!$A$4:$A$200,MATCH(ROWS($A$12:A12),今日戰報!$M$4:$M$200,0)),"")} -> 鄭宗哲 | B12: {=IFERROR(INDEX(今日戰報!$H$4:$H$200,MATCH(ROWS($A$12:A12),今日戰報!$M$4:$M$200,0)),"")} -> 5AB，1H，3K，AVG.262，OBP.395，SLG.508​ | I12: 合計 | J12: =SUM(J3:J11) -> 40
A13: {=IFERROR(INDEX(今日戰報!$A$4:$A$200,MATCH(ROWS($A$12:A13),今日戰報!$M$4:$M$200,0)),"")} -> Corbin Carroll | B13: {=IFERROR(INDEX(今日戰報!$H$4:$H$200,MATCH(ROWS($A$12:A13),今日戰報!$M$4:$M$200,0)),"")} -> 4AB，0H，1K，AVG.296，OBP.396，SLG.580
A14: {=IFERROR(INDEX(今日戰報!$A$4:$A$200,MATCH(ROWS($A$12:A14),今日戰報!$M$4:$M$200,0)),"")} -> Jonathon Long | B14: {=IFERROR(INDEX(今日戰報!$H$4:$H$200,MATCH(ROWS($A$12:A14),今日戰報!$M$4:$M$200,0)),"")} -> 4AB，0H，AVG.267，OBP.370，SLG.395
A15: {=IFERROR(INDEX(今日戰報!$A$4:$A$200,MATCH(ROWS($A$12:A15),今日戰報!$M$4:$M$200,0)),"")} | B15: {=IFERROR(INDEX(今日戰報!$H$4:$H$200,MATCH(ROWS($A$12:A15),今日戰報!$M$4:$M$200,0)),"")}
A16: {=IFERROR(INDEX(今日戰報!$A$4:$A$200,MATCH(ROWS($A$12:A16),今日戰報!$M$4:$M$200,0)),"")} | B16: {=IFERROR(INDEX(今日戰報!$H$4:$H$200,MATCH(ROWS($A$12:A16),今日戰報!$M$4:$M$200,0)),"")}
A17: {=IFERROR(INDEX(今日戰報!$A$4:$A$200,MATCH(ROWS($A$12:A17),今日戰報!$M$4:$M$200,0)),"")} | B17: {=IFERROR(INDEX(今日戰報!$H$4:$H$200,MATCH(ROWS($A$12:A17),今日戰報!$M$4:$M$200,0)),"")}
A18: {=IFERROR(INDEX(今日戰報!$A$4:$A$200,MATCH(ROWS($A$12:A18),今日戰報!$M$4:$M$200,0)),"")} | B18: {=IFERROR(INDEX(今日戰報!$H$4:$H$200,MATCH(ROWS($A$12:A18),今日戰報!$M$4:$M$200,0)),"")}
A19: 球員異動狀態
A20: 球員 | B20: 異動 | C20: 狀態
A21: {=IFERROR(INDEX(總表!$A$2:$A$200,MATCH(ROWS($A$21:A21),總表!$V$2:$V$200,0)),"")} -> 劉致榮 | B21: {=IF($A21="","",IFERROR(INDEX(異動資料源!$H$2:$H$200,MATCH($A21,異動資料源!$A$2:$A$200,0)),""))} | C21: =IF($A21="","",IFERROR(INDEX(異動資料源!$M$2:$M$200,MATCH($A21,異動資料源!$A$2:$A$200,0)),"")) -> ⚕ IL(39/60)
A22: {=IFERROR(INDEX(總表!$A$2:$A$200,MATCH(ROWS($A$21:A22),總表!$V$2:$V$200,0)),"")} -> 沈家羲 | B22: {=IF($A22="","",IFERROR(INDEX(異動資料源!$H$2:$H$200,MATCH($A22,異動資料源!$A$2:$A$200,0)),""))} | C22: =IF($A22="","",IFERROR(INDEX(異動資料源!$M$2:$M$200,MATCH($A22,異動資料源!$A$2:$A$200,0)),"")) -> ⚕ IL(39/60)
A23: {=IFERROR(INDEX(總表!$A$2:$A$200,MATCH(ROWS($A$21:A23),總表!$V$2:$V$200,0)),"")} | B23: {=IF($A23="","",IFERROR(INDEX(異動資料源!$H$2:$H$200,MATCH($A23,異動資料源!$A$2:$A$200,0)),""))} | C23: =IF($A23="","",IFERROR(INDEX(異動資料源!$M$2:$M$200,MATCH($A23,異動資料源!$A$2:$A$200,0)),""))
A24: {=IFERROR(INDEX(總表!$A$2:$A$200,MATCH(ROWS($A$21:A24),總表!$V$2:$V$200,0)),"")} | B24: {=IF($A24="","",IFERROR(INDEX(異動資料源!$H$2:$H$200,MATCH($A24,異動資料源!$A$2:$A$200,0)),""))} | C24: =IF($A24="","",IFERROR(INDEX(異動資料源!$M$2:$M$200,MATCH($A24,異動資料源!$A$2:$A$200,0)),""))
A25: {=IFERROR(INDEX(總表!$A$2:$A$200,MATCH(ROWS($A$21:A25),總表!$V$2:$V$200,0)),"")} | B25: {=IF($A25="","",IFERROR(INDEX(異動資料源!$H$2:$H$200,MATCH($A25,異動資料源!$A$2:$A$200,0)),""))} | C25: =IF($A25="","",IFERROR(INDEX(異動資料源!$M$2:$M$200,MATCH($A25,異動資料源!$A$2:$A$200,0)),""))
A26: =IFERROR(INDEX(總表!$A$2:$A$200,MATCH(ROWS($A$21:A26),總表!$V$2:$V$200,0)),"") | B26: =IF($A26="","",IFERROR(INDEX(異動資料源!$H$2:$H$200,MATCH($A26,異動資料源!$A$2:$A$200,0)),"")) | C26: =IF($A26="","",IFERROR(INDEX(異動資料源!$M$2:$M$200,MATCH($A26,異動資料源!$A$2:$A$200,0)),""))
A27: =IFERROR(INDEX(總表!$A$2:$A$200,MATCH(ROWS($A$21:A27),總表!$V$2:$V$200,0)),"") | B27: =IF($A27="","",IFERROR(INDEX(異動資料源!$H$2:$H$200,MATCH($A27,異動資料源!$A$2:$A$200,0)),"")) | C27: =IF($A27="","",IFERROR(INDEX(異動資料源!$M$2:$M$200,MATCH($A27,異動資料源!$A$2:$A$200,0)),""))
A28: =IFERROR(INDEX(總表!$A$2:$A$200,MATCH(ROWS($A$21:A28),總表!$V$2:$V$200,0)),"") | B28: =IF($A28="","",IFERROR(INDEX(異動資料源!$H$2:$H$200,MATCH($A28,異動資料源!$A$2:$A$200,0)),"")) | C28: =IF($A28="","",IFERROR(INDEX(異動資料源!$M$2:$M$200,MATCH($A28,異動資料源!$A$2:$A$200,0)),""))
A29: =IFERROR(INDEX(總表!$A$2:$A$200,MATCH(ROWS($A$21:A29),總表!$V$2:$V$200,0)),"") | B29: =IF($A29="","",IFERROR(INDEX(異動資料源!$H$2:$H$200,MATCH($A29,異動資料源!$A$2:$A$200,0)),"")) | C29: =IF($A29="","",IFERROR(INDEX(異動資料源!$M$2:$M$200,MATCH($A29,異動資料源!$A$2:$A$200,0)),""))
A30: =IFERROR(INDEX(總表!$A$2:$A$200,MATCH(ROWS($A$21:A30),總表!$V$2:$V$200,0)),"") | B30: =IF($A30="","",IFERROR(INDEX(異動資料源!$H$2:$H$200,MATCH($A30,異動資料源!$A$2:$A$200,0)),"")) | C30: =IF($A30="","",IFERROR(INDEX(異動資料源!$M$2:$M$200,MATCH($A30,異動資料源!$A$2:$A$200,0)),""))
A31: =IFERROR(INDEX(總表!$A$2:$A$200,MATCH(ROWS($A$21:A31),總表!$V$2:$V$200,0)),"") | B31: =IF($A31="","",IFERROR(INDEX(異動資料源!$H$2:$H$200,MATCH($A31,異動資料源!$A$2:$A$200,0)),"")) | C31: =IF($A31="","",IFERROR(INDEX(異動資料源!$M$2:$M$200,MATCH($A31,異動資料源!$A$2:$A$200,0)),""))
A32: =IFERROR(INDEX(總表!$A$2:$A$200,MATCH(ROWS($A$21:A32),總表!$V$2:$V$200,0)),"") | B32: =IF($A32="","",IFERROR(INDEX(異動資料源!$H$2:$H$200,MATCH($A32,異動資料源!$A$2:$A$200,0)),"")) | C32: =IF($A32="","",IFERROR(INDEX(異動資料源!$M$2:$M$200,MATCH($A32,異動資料源!$A$2:$A$200,0)),""))
A33: =IFERROR(INDEX(總表!$A$2:$A$200,MATCH(ROWS($A$21:A33),總表!$V$2:$V$200,0)),"") | B33: =IF($A33="","",IFERROR(INDEX(異動資料源!$H$2:$H$200,MATCH($A33,異動資料源!$A$2:$A$200,0)),"")) | C33: =IF($A33="","",IFERROR(INDEX(異動資料源!$M$2:$M$200,MATCH($A33,異動資料源!$A$2:$A$200,0)),""))
A34: =IFERROR(INDEX(總表!$A$2:$A$200,MATCH(ROWS($A$21:A34),總表!$V$2:$V$200,0)),"") | B34: =IF($A34="","",IFERROR(INDEX(異動資料源!$H$2:$H$200,MATCH($A34,異動資料源!$A$2:$A$200,0)),"")) | C34: =IF($A34="","",IFERROR(INDEX(異動資料源!$M$2:$M$200,MATCH($A34,異動資料源!$A$2:$A$200,0)),""))
A35: =IFERROR(INDEX(總表!$A$2:$A$200,MATCH(ROWS($A$21:A35),總表!$V$2:$V$200,0)),"") | B35: =IF($A35="","",IFERROR(INDEX(異動資料源!$H$2:$H$200,MATCH($A35,異動資料源!$A$2:$A$200,0)),"")) | C35: =IF($A35="","",IFERROR(INDEX(異動資料源!$M$2:$M$200,MATCH($A35,異動資料源!$A$2:$A$200,0)),""))

Sheet 今日戰報
A1: 旅外就是神｜今日戰報
A2: 球員 | B2: 分類 | C2: 層級 | D2: 守位 | E2: 球隊 | F2: 是否先發/前次出賽 | G2: 對手 | H2: 今日成績 | I2: 排序欄1 | J2: 排序欄2 | K2: 排序欄3 | L2: 首頁投手序 | M2: 首頁野手序
A3: 投手 | B3: =IFERROR(INDEX(總表!$B:$B,MATCH($A3,總表!$A:$A,0)),"") | C3: =IFERROR(INDEX(總表!$G:$G,MATCH($A3,總表!$A:$A,0)),"") | D3: =IFERROR(INDEX(總表!$C:$C,MATCH($A3,總表!$A:$A,0)),"") | E3: =IFERROR(INDEX(總表!$F:$F,MATCH($A3,總表!$A:$A,0)),"") | I3: =IF($A3="投手",1,IF($D3="投手",2,IF($A3="野手",3,IF(OR($D3="野手",$D3="內野手",$D3="外野手",$D3="捕手"),4,99)))) -> 1 | J3: {=IF($B3="旅美",1,IF($B3="旅日",2,IF($B3="旅韓",3,IF($B3="台裔",4,IF($B3<>"",5,99)))))} -> 99 | K3: {=IF($C3="MLB",1,IF($C3="3A",2,IF($C3="2A",3,IF(OR($C3="A+",$C3="高A"),4,IF($C3="1A",5,IF(OR($C3="RK",$C3="Rookie"),6,IF($C3="日職一軍",7,IF($C3="日職二軍",8,IF(OR($C3="韓職一軍",$C3="KBO"),9,IF($C3<>"",10,99))))))))))} -> 99 | L3: =IF(AND($D3="投手",LEFT($F3,3)="YES",OR($C3="MLB",$C3="3A",$C3="2A",$C3="日職一軍",$C3="韓職一軍",$C3="KBO")),COUNT($L2:L$3)+1,"") | M3: =IF(AND($D3<>"投手",$D3<>"",LEFT($F3,3)="YES",OR($C3="MLB",$C3="3A",$C3="2A",$C3="日職一軍",$C3="韓職一軍",$C3="KBO")),COUNT($M2:M$3)+1,"")
A4: 鄧愷威 | B4: =IFERROR(INDEX(總表!$B:$B,MATCH($A4,總表!$A:$A,0)),"") -> 旅美 | C4: =IFERROR(INDEX(總表!$G:$G,MATCH($A4,總表!$A:$A,0)),"") -> MLB | D4: =IFERROR(INDEX(總表!$C:$C,MATCH($A4,總表!$A:$A,0)),"") -> 投手 | E4: =IFERROR(INDEX(總表!$F:$F,MATCH($A4,總表!$A:$A,0)),"") -> 休士頓太空人 | F4: NO(4/21) | I4: =IF($A4="投手",1,IF($D4="投手",2,IF($A4="野手",3,IF(OR($D4="野手",$D4="內野手",$D4="外野手",$D4="捕手"),4,99)))) -> 2 | J4: {=IF($B4="旅美",1,IF($B4="旅日",2,IF($B4="旅韓",3,IF($B4="台裔",4,IF($B4<>"",5,99)))))} -> 1 | K4: {=IF($C4="MLB",1,IF($C4="3A",2,IF($C4="2A",3,IF(OR($C4="A+",$C4="高A"),4,IF($C4="1A",5,IF(OR($C4="RK",$C4="Rookie"),6,IF($C4="日職一軍",7,IF($C4="日職二軍",8,IF(OR($C4="韓職一軍",$C4="KBO"),9,IF($C4<>"",10,99))))))))))} -> 1 | L4: =IF(AND($D4="投手",LEFT($F4,3)="YES",OR($C4="MLB",$C4="3A",$C4="2A",$C4="日職一軍",$C4="韓職一軍",$C4="KBO")),COUNT($L$3:L3)+1,"") | M4: =IF(AND($D4<>"投手",$D4<>"",LEFT($F4,3)="YES",OR($C4="MLB",$C4="3A",$C4="2A",$C4="日職一軍",$C4="韓職一軍",$C4="KBO")),COUNT($M$3:M3)+1,"")
A5: 林昱珉 | B5: =IFERROR(INDEX(總表!$B:$B,MATCH($A5,總表!$A:$A,0)),"") -> 旅美 | C5: =IFERROR(INDEX(總表!$G:$G,MATCH($A5,總表!$A:$A,0)),"") -> 3A | D5: =IFERROR(INDEX(總表!$C:$C,MATCH($A5,總表!$A:$A,0)),"") -> 投手 | E5: =IFERROR(INDEX(總表!$F:$F,MATCH($A5,總表!$A:$A,0)),"") -> 亞利桑那響尾蛇 | F5: YES | H5: 0.2IP，32P，5H，5R，2ER，2K，ERA 6.35，WHIP 2.12(L) | I5: =IF($A5="投手",1,IF($D5="投手",2,IF($A5="野手",3,IF(OR($D5="野手",$D5="內野手",$D5="外野手",$D5="捕手"),4,99)))) -> 2 | J5: {=IF($B5="旅美",1,IF($B5="旅日",2,IF($B5="旅韓",3,IF($B5="台裔",4,IF($B5<>"",5,99)))))} -> 1 | K5: {=IF($C5="MLB",1,IF($C5="3A",2,IF($C5="2A",3,IF(OR($C5="A+",$C5="高A"),4,IF($C5="1A",5,IF(OR($C5="RK",$C5="Rookie"),6,IF($C5="日職一軍",7,IF($C5="日職二軍",8,IF(OR($C5="韓職一軍",$C5="KBO"),9,IF($C5<>"",10,99))))))))))} -> 2 | L5: =IF(AND($D5="投手",LEFT($F5,3)="YES",OR($C5="MLB",$C5="3A",$C5="2A",$C5="日職一軍",$C5="韓職一軍",$C5="KBO")),COUNT($L$3:L4)+1,"") -> 1 | M5: =IF(AND($D5<>"投手",$D5<>"",LEFT($F5,3)="YES",OR($C5="MLB",$C5="3A",$C5="2A",$C5="日職一軍",$C5="韓職一軍",$C5="KBO")),COUNT($M$3:M4)+1,"")
A6: 林振瑋 | B6: =IFERROR(INDEX(總表!$B:$B,MATCH($A6,總表!$A:$A,0)),"") -> 旅美 | C6: =IFERROR(INDEX(總表!$G:$G,MATCH($A6,總表!$A:$A,0)),"") -> 2A | D6: =IFERROR(INDEX(總表!$C:$C,MATCH($A6,總表!$A:$A,0)),"") -> 投手 | E6: =IFERROR(INDEX(總表!$F:$F,MATCH($A6,總表!$A:$A,0)),"") -> 聖路易紅雀 | F6: NO(4/18) | I6: =IF($A6="投手",1,IF($D6="投手",2,IF($A6="野手",3,IF(OR($D6="野手",$D6="內野手",$D6="外野手",$D6="捕手"),4,99)))) -> 2 | J6: {=IF($B6="旅美",1,IF($B6="旅日",2,IF($B6="旅韓",3,IF($B6="台裔",4,IF($B6<>"",5,99)))))} -> 1 | K6: {=IF($C6="MLB",1,IF($C6="3A",2,IF($C6="2A",3,IF(OR($C6="A+",$C6="高A"),4,IF($C6="1A",5,IF(OR($C6="RK",$C6="Rookie"),6,IF($C6="日職一軍",7,IF($C6="日職二軍",8,IF(OR($C6="韓職一軍",$C6="KBO"),9,IF($C6<>"",10,99))))))))))} -> 3 | L6: =IF(AND($D6="投手",LEFT($F6,3)="YES",OR($C6="MLB",$C6="3A",$C6="2A",$C6="日職一軍",$C6="韓職一軍",$C6="KBO")),COUNT($L$3:L5)+1,"") | M6: =IF(AND($D6<>"投手",$D6<>"",LEFT($F6,3)="YES",OR($C6="MLB",$C6="3A",$C6="2A",$C6="日職一軍",$C6="韓職一軍",$C6="KBO")),COUNT($M$3:M5)+1,"")
A7: 莊陳仲敖 | B7: =IFERROR(INDEX(總表!$B:$B,MATCH($A7,總表!$A:$A,0)),"") -> 旅美 | C7: =IFERROR(INDEX(總表!$G:$G,MATCH($A7,總表!$A:$A,0)),"") -> 2A | D7: =IFERROR(INDEX(總表!$C:$C,MATCH($A7,總表!$A:$A,0)),"") -> 投手 | E7: =IFERROR(INDEX(總表!$F:$F,MATCH($A7,總表!$A:$A,0)),"") -> 奧克蘭運動家 | F7: NO(4/18) | I7: =IF($A7="投手",1,IF($D7="投手",2,IF($A7="野手",3,IF(OR($D7="野手",$D7="內野手",$D7="外野手",$D7="捕手"),4,99)))) -> 2 | J7: {=IF($B7="旅美",1,IF($B7="旅日",2,IF($B7="旅韓",3,IF($B7="台裔",4,IF($B7<>"",5,99)))))} -> 1 | K7: {=IF($C7="MLB",1,IF($C7="3A",2,IF($C7="2A",3,IF(OR($C7="A+",$C7="高A"),4,IF($C7="1A",5,IF(OR($C7="RK",$C7="Rookie"),6,IF($C7="日職一軍",7,IF($C7="日職二軍",8,IF(OR($C7="韓職一軍",$C7="KBO"),9,IF($C7<>"",10,99))))))))))} -> 3 | L7: =IF(AND($D7="投手",LEFT($F7,3)="YES",OR($C7="MLB",$C7="3A",$C7="2A",$C7="日職一軍",$C7="韓職一軍",$C7="KBO")),COUNT($L$3:L6)+1,"") | M7: =IF(AND($D7<>"投手",$D7<>"",LEFT($F7,3)="YES",OR($C7="MLB",$C7="3A",$C7="2A",$C7="日職一軍",$C7="韓職一軍",$C7="KBO")),COUNT($M$3:M6)+1,"")
A8: 林維恩 | B8: =IFERROR(INDEX(總表!$B:$B,MATCH($A8,總表!$A:$A,0)),"") -> 旅美 | C8: =IFERROR(INDEX(總表!$G:$G,MATCH($A8,總表!$A:$A,0)),"") -> 2A | D8: =IFERROR(INDEX(總表!$C:$C,MATCH($A8,總表!$A:$A,0)),"") -> 投手 | E8: =IFERROR(INDEX(總表!$F:$F,MATCH($A8,總表!$A:$A,0)),"") -> 奧克蘭運動家 | F8: NO(4/19) | I8: =IF($A8="投手",1,IF($D8="投手",2,IF($A8="野手",3,IF(OR($D8="野手",$D8="內野手",$D8="外野手",$D8="捕手"),4,99)))) -> 2 | J8: {=IF($B8="旅美",1,IF($B8="旅日",2,IF($B8="旅韓",3,IF($B8="台裔",4,IF($B8<>"",5,99)))))} -> 1 | K8: {=IF($C8="MLB",1,IF($C8="3A",2,IF($C8="2A",3,IF(OR($C8="A+",$C8="高A"),4,IF($C8="1A",5,IF(OR($C8="RK",$C8="Rookie"),6,IF($C8="日職一軍",7,IF($C8="日職二軍",8,IF(OR($C8="韓職一軍",$C8="KBO"),9,IF($C8<>"",10,99))))))))))} -> 3 | L8: =IF(AND($D8="投手",LEFT($F8,3)="YES",OR($C8="MLB",$C8="3A",$C8="2A",$C8="日職一軍",$C8="韓職一軍",$C8="KBO")),COUNT($L$3:L7)+1,"") | M8: =IF(AND($D8<>"投手",$D8<>"",LEFT($F8,3)="YES",OR($C8="MLB",$C8="3A",$C8="2A",$C8="日職一軍",$C8="韓職一軍",$C8="KBO")),COUNT($M$3:M7)+1,"")
A9: 陳柏毓 | B9: =IFERROR(INDEX(總表!$B:$B,MATCH($A9,總表!$A:$A,0)),"") -> 旅美 | C9: =IFERROR(INDEX(總表!$G:$G,MATCH($A9,總表!$A:$A,0)),"") -> 2A | D9: =IFERROR(INDEX(總表!$C:$C,MATCH($A9,總表!$A:$A,0)),"") -> 投手 | E9: =IFERROR(INDEX(總表!$F:$F,MATCH($A9,總表!$A:$A,0)),"") -> 匹茲堡海盜 | F9: YES | H9: 4.0IP，4H，2R，1ER，1HR，4K，2BB，73P,ERA 5.65，WHIP 1.47 (無關勝敗) | I9: =IF($A9="投手",1,IF($D9="投手",2,IF($A9="野手",3,IF(OR($D9="野手",$D9="內野手",$D9="外野手",$D9="捕手"),4,99)))) -> 2 | J9: {=IF($B9="旅美",1,IF($B9="旅日",2,IF($B9="旅韓",3,IF($B9="台裔",4,IF($B9<>"",5,99)))))} -> 1 | K9: {=IF($C9="MLB",1,IF($C9="3A",2,IF($C9="2A",3,IF(OR($C9="A+",$C9="高A"),4,IF($C9="1A",5,IF(OR($C9="RK",$C9="Rookie"),6,IF($C9="日職一軍",7,IF($C9="日職二軍",8,IF(OR($C9="韓職一軍",$C9="KBO"),9,IF($C9<>"",10,99))))))))))} -> 3 | L9: =IF(AND($D9="投手",LEFT($F9,3)="YES",OR($C9="MLB",$C9="3A",$C9="2A",$C9="日職一軍",$C9="韓職一軍",$C9="KBO")),COUNT($L$3:L8)+1,"") -> 2 | M9: =IF(AND($D9<>"投手",$D9<>"",LEFT($F9,3)="YES",OR($C9="MLB",$C9="3A",$C9="2A",$C9="日職一軍",$C9="韓職一軍",$C9="KBO")),COUNT($M$3:M8)+1,"")
A10: 劉致榮 | B10: =IFERROR(INDEX(總表!$B:$B,MATCH($A10,總表!$A:$A,0)),"") -> 旅美 | C10: =IFERROR(INDEX(總表!$G:$G,MATCH($A10,總表!$A:$A,0)),"") -> 2A | D10: =IFERROR(INDEX(總表!$C:$C,MATCH($A10,總表!$A:$A,0)),"") -> 投手 | E10: =IFERROR(INDEX(總表!$F:$F,MATCH($A10,總表!$A:$A,0)),"") -> 波士頓紅襪 | F10: NO(38/60天) | I10: =IF($A10="投手",1,IF($D10="投手",2,IF($A10="野手",3,IF(OR($D10="野手",$D10="內野手",$D10="外野手",$D10="捕手"),4,99)))) -> 2 | J10: {=IF($B10="旅美",1,IF($B10="旅日",2,IF($B10="旅韓",3,IF($B10="台裔",4,IF($B10<>"",5,99)))))} -> 1 | K10: {=IF($C10="MLB",1,IF($C10="3A",2,IF($C10="2A",3,IF(OR($C10="A+",$C10="高A"),4,IF($C10="1A",5,IF(OR($C10="RK",$C10="Rookie"),6,IF($C10="日職一軍",7,IF($C10="日職二軍",8,IF(OR($C10="韓職一軍",$C10="KBO"),9,IF($C10<>"",10,99))))))))))} -> 3 | L10: =IF(AND($D10="投手",LEFT($F10,3)="YES",OR($C10="MLB",$C10="3A",$C10="2A",$C10="日職一軍",$C10="韓職一軍",$C10="KBO")),COUNT($L$3:L9)+1,"") | M10: =IF(AND($D10<>"投手",$D10<>"",LEFT($F10,3)="YES",OR($C10="MLB",$C10="3A",$C10="2A",$C10="日職一軍",$C10="韓職一軍",$C10="KBO")),COUNT($M$3:M9)+1,"")
A11: 沙子宸 | B11: =IFERROR(INDEX(總表!$B:$B,MATCH($A11,總表!$A:$A,0)),"") -> 旅美 | C11: =IFERROR(INDEX(總表!$G:$G,MATCH($A11,總表!$A:$A,0)),"") -> A+ | D11: =IFERROR(INDEX(總表!$C:$C,MATCH($A11,總表!$A:$A,0)),"") -> 投手 | E11: =IFERROR(INDEX(總表!$F:$F,MATCH($A11,總表!$A:$A,0)),"") -> 奧克蘭運動家 | F11: NO(4/20) | I11: =IF($A11="投手",1,IF($D11="投手",2,IF($A11="野手",3,IF(OR($D11="野手",$D11="內野手",$D11="外野手",$D11="捕手"),4,99)))) -> 2 | J11: {=IF($B11="旅美",1,IF($B11="旅日",2,IF($B11="旅韓",3,IF($B11="台裔",4,IF($B11<>"",5,99)))))} -> 1 | K11: {=IF($C11="MLB",1,IF($C11="3A",2,IF($C11="2A",3,IF(OR($C11="A+",$C11="高A"),4,IF($C11="1A",5,IF(OR($C11="RK",$C11="Rookie"),6,IF($C11="日職一軍",7,IF($C11="日職二軍",8,IF(OR($C11="韓職一軍",$C11="KBO"),9,IF($C11<>"",10,99))))))))))} -> 4 | L11: =IF(AND($D11="投手",LEFT($F11,3)="YES",OR($C11="MLB",$C11="3A",$C11="2A",$C11="日職一軍",$C11="韓職一軍",$C11="KBO")),COUNT($L$3:L10)+1,"") | M11: =IF(AND($D11<>"投手",$D11<>"",LEFT($F11,3)="YES",OR($C11="MLB",$C11="3A",$C11="2A",$C11="日職一軍",$C11="韓職一軍",$C11="KBO")),COUNT($M$3:M10)+1,"")
A12: 張弘稜 | B12: =IFERROR(INDEX(總表!$B:$B,MATCH($A12,總表!$A:$A,0)),"") -> 旅美 | C12: =IFERROR(INDEX(總表!$G:$G,MATCH($A12,總表!$A:$A,0)),"") -> A+ | D12: =IFERROR(INDEX(總表!$C:$C,MATCH($A12,總表!$A:$A,0)),"") -> 投手 | E12: =IFERROR(INDEX(總表!$F:$F,MATCH($A12,總表!$A:$A,0)),"") -> 匹茲堡海盜 | F12: YES | H12: 5.0IP，75P，6H，5R，5ER，2HR，4K，3BB，ERA 10.66，WHIP 1.89 (W) | I12: =IF($A12="投手",1,IF($D12="投手",2,IF($A12="野手",3,IF(OR($D12="野手",$D12="內野手",$D12="外野手",$D12="捕手"),4,99)))) -> 2 | J12: {=IF($B12="旅美",1,IF($B12="旅日",2,IF($B12="旅韓",3,IF($B12="台裔",4,IF($B12<>"",5,99)))))} -> 1 | K12: {=IF($C12="MLB",1,IF($C12="3A",2,IF($C12="2A",3,IF(OR($C12="A+",$C12="高A"),4,IF($C12="1A",5,IF(OR($C12="RK",$C12="Rookie"),6,IF($C12="日職一軍",7,IF($C12="日職二軍",8,IF(OR($C12="韓職一軍",$C12="KBO"),9,IF($C12<>"",10,99))))))))))} -> 4 | L12: =IF(AND($D12="投手",LEFT($F12,3)="YES",OR($C12="MLB",$C12="3A",$C12="2A",$C12="日職一軍",$C12="韓職一軍",$C12="KBO")),COUNT($L$3:L11)+1,"") | M12: =IF(AND($D12<>"投手",$D12<>"",LEFT($F12,3)="YES",OR($C12="MLB",$C12="3A",$C12="2A",$C12="日職一軍",$C12="韓職一軍",$C12="KBO")),COUNT($M$3:M11)+1,"")
A13: 沈家羲 | B13: =IFERROR(INDEX(總表!$B:$B,MATCH($A13,總表!$A:$A,0)),"") -> 旅美 | C13: =IFERROR(INDEX(總表!$G:$G,MATCH($A13,總表!$A:$A,0)),"") -> 1A | D13: =IFERROR(INDEX(總表!$C:$C,MATCH($A13,總表!$A:$A,0)),"") -> 投手 | E13: =IFERROR(INDEX(總表!$F:$F,MATCH($A13,總表!$A:$A,0)),"") -> 西雅圖水手 | F13: NO(38/60天) | I13: =IF($A13="投手",1,IF($D13="投手",2,IF($A13="野手",3,IF(OR($D13="野手",$D13="內野手",$D13="外野手",$D13="捕手"),4,99)))) -> 2 | J13: {=IF($B13="旅美",1,IF($B13="旅日",2,IF($B13="旅韓",3,IF($B13="台裔",4,IF($B13<>"",5,99)))))} -> 1 | K13: {=IF($C13="MLB",1,IF($C13="3A",2,IF($C13="2A",3,IF(OR($C13="A+",$C13="高A"),4,IF($C13="1A",5,IF(OR($C13="RK",$C13="Rookie"),6,IF($C13="日職一軍",7,IF($C13="日職二軍",8,IF(OR($C13="韓職一軍",$C13="KBO"),9,IF($C13<>"",10,99))))))))))} -> 5 | L13: =IF(AND($D13="投手",LEFT($F13,3)="YES",OR($C13="MLB",$C13="3A",$C13="2A",$C13="日職一軍",$C13="韓職一軍",$C13="KBO")),COUNT($L$3:L12)+1,"") | M13: =IF(AND($D13<>"投手",$D13<>"",LEFT($F13,3)="YES",OR($C13="MLB",$C13="3A",$C13="2A",$C13="日職一軍",$C13="韓職一軍",$C13="KBO")),COUNT($M$3:M12)+1,"")
A14: 林盛恩 | B14: =IFERROR(INDEX(總表!$B:$B,MATCH($A14,總表!$A:$A,0)),"") -> 旅美 | C14: =IFERROR(INDEX(總表!$G:$G,MATCH($A14,總表!$A:$A,0)),"") -> 1A | D14: =IFERROR(INDEX(總表!$C:$C,MATCH($A14,總表!$A:$A,0)),"") -> 投手 | E14: =IFERROR(INDEX(總表!$F:$F,MATCH($A14,總表!$A:$A,0)),"") -> 辛辛那提紅人 | F14: NO(4/19) | I14: =IF($A14="投手",1,IF($D14="投手",2,IF($A14="野手",3,IF(OR($D14="野手",$D14="內野手",$D14="外野手",$D14="捕手"),4,99)))) -> 2 | J14: {=IF($B14="旅美",1,IF($B14="旅日",2,IF($B14="旅韓",3,IF($B14="台裔",4,IF($B14<>"",5,99)))))} -> 1 | K14: {=IF($C14="MLB",1,IF($C14="3A",2,IF($C14="2A",3,IF(OR($C14="A+",$C14="高A"),4,IF($C14="1A",5,IF(OR($C14="RK",$C14="Rookie"),6,IF($C14="日職一軍",7,IF($C14="日職二軍",8,IF(OR($C14="韓職一軍",$C14="KBO"),9,IF($C14<>"",10,99))))))))))} -> 5 | L14: =IF(AND($D14="投手",LEFT($F14,3)="YES",OR($C14="MLB",$C14="3A",$C14="2A",$C14="日職一軍",$C14="韓職一軍",$C14="KBO")),COUNT($L$3:L13)+1,"") | M14: =IF(AND($D14<>"投手",$D14<>"",LEFT($F14,3)="YES",OR($C14="MLB",$C14="3A",$C14="2A",$C14="日職一軍",$C14="韓職一軍",$C14="KBO")),COUNT($M$3:M13)+1,"")
A15: 黃仲翔 | B15: =IFERROR(INDEX(總表!$B:$B,MATCH($A15,總表!$A:$A,0)),"") -> 旅美 | C15: =IFERROR(INDEX(總表!$G:$G,MATCH($A15,總表!$A:$A,0)),"") -> 1A | D15: =IFERROR(INDEX(總表!$C:$C,MATCH($A15,總表!$A:$A,0)),"") -> 投手 | E15: =IFERROR(INDEX(總表!$F:$F,MATCH($A15,總表!$A:$A,0)),"") -> 亞利桑那響尾蛇 | F15: NO(4/18) | I15: =IF($A15="投手",1,IF($D15="投手",2,IF($A15="野手",3,IF(OR($D15="野手",$D15="內野手",$D15="外野手",$D15="捕手"),4,99)))) -> 2 | J15: {=IF($B15="旅美",1,IF($B15="旅日",2,IF($B15="旅韓",3,IF($B15="台裔",4,IF($B15<>"",5,99)))))} -> 1 | K15: {=IF($C15="MLB",1,IF($C15="3A",2,IF($C15="2A",3,IF(OR($C15="A+",$C15="高A"),4,IF($C15="1A",5,IF(OR($C15="RK",$C15="Rookie"),6,IF($C15="日職一軍",7,IF($C15="日職二軍",8,IF(OR($C15="韓職一軍",$C15="KBO"),9,IF($C15<>"",10,99))))))))))} -> 5 | L15: =IF(AND($D15="投手",LEFT($F15,3)="YES",OR($C15="MLB",$C15="3A",$C15="2A",$C15="日職一軍",$C15="韓職一軍",$C15="KBO")),COUNT($L$3:L14)+1,"") | M15: =IF(AND($D15<>"投手",$D15<>"",LEFT($F15,3)="YES",OR($C15="MLB",$C15="3A",$C15="2A",$C15="日職一軍",$C15="韓職一軍",$C15="KBO")),COUNT($M$3:M14)+1,"")
A16: 潘文輝 | B16: =IFERROR(INDEX(總表!$B:$B,MATCH($A16,總表!$A:$A,0)),"") -> 旅美 | C16: =IFERROR(INDEX(總表!$G:$G,MATCH($A16,總表!$A:$A,0)),"") -> 1A | D16: =IFERROR(INDEX(總表!$C:$C,MATCH($A16,總表!$A:$A,0)),"") -> 投手 | E16: =IFERROR(INDEX(總表!$F:$F,MATCH($A16,總表!$A:$A,0)),"") -> 費城費城人 | F16: NO(4/23) | I16: =IF($A16="投手",1,IF($D16="投手",2,IF($A16="野手",3,IF(OR($D16="野手",$D16="內野手",$D16="外野手",$D16="捕手"),4,99)))) -> 2 | J16: {=IF($B16="旅美",1,IF($B16="旅日",2,IF($B16="旅韓",3,IF($B16="台裔",4,IF($B16<>"",5,99)))))} -> 1 | K16: {=IF($C16="MLB",1,IF($C16="3A",2,IF($C16="2A",3,IF(OR($C16="A+",$C16="高A"),4,IF($C16="1A",5,IF(OR($C16="RK",$C16="Rookie"),6,IF($C16="日職一軍",7,IF($C16="日職二軍",8,IF(OR($C16="韓職一軍",$C16="KBO"),9,IF($C16<>"",10,99))))))))))} -> 5 | L16: =IF(AND($D16="投手",LEFT($F16,3)="YES",OR($C16="MLB",$C16="3A",$C16="2A",$C16="日職一軍",$C16="韓職一軍",$C16="KBO")),COUNT($L$3:L15)+1,"") | M16: =IF(AND($D16<>"投手",$D16<>"",LEFT($F16,3)="YES",OR($C16="MLB",$C16="3A",$C16="2A",$C16="日職一軍",$C16="韓職一軍",$C16="KBO")),COUNT($M$3:M15)+1,"")
A17: 李晨薰 | B17: =IFERROR(INDEX(總表!$B:$B,MATCH($A17,總表!$A:$A,0)),"") -> 旅美 | C17: =IFERROR(INDEX(總表!$G:$G,MATCH($A17,總表!$A:$A,0)),"") -> RK | D17: =IFERROR(INDEX(總表!$C:$C,MATCH($A17,總表!$A:$A,0)),"") -> 投手 | E17: =IFERROR(INDEX(總表!$F:$F,MATCH($A17,總表!$A:$A,0)),"") -> 舊金山巨人 | F17: NO | I17: =IF($A17="投手",1,IF($D17="投手",2,IF($A17="野手",3,IF(OR($D17="野手",$D17="內野手",$D17="外野手",$D17="捕手"),4,99)))) -> 2 | J17: {=IF($B17="旅美",1,IF($B17="旅日",2,IF($B17="旅韓",3,IF($B17="台裔",4,IF($B17<>"",5,99)))))} -> 1 | K17: {=IF($C17="MLB",1,IF($C17="3A",2,IF($C17="2A",3,IF(OR($C17="A+",$C17="高A"),4,IF($C17="1A",5,IF(OR($C17="RK",$C17="Rookie"),6,IF($C17="日職一軍",7,IF($C17="日職二軍",8,IF(OR($C17="韓職一軍",$C17="KBO"),9,IF($C17<>"",10,99))))))))))} -> 6 | L17: =IF(AND($D17="投手",LEFT($F17,3)="YES",OR($C17="MLB",$C17="3A",$C17="2A",$C17="日職一軍",$C17="韓職一軍",$C17="KBO")),COUNT($L$3:L16)+1,"") | M17: =IF(AND($D17<>"投手",$D17<>"",LEFT($F17,3)="YES",OR($C17="MLB",$C17="3A",$C17="2A",$C17="日職一軍",$C17="韓職一軍",$C17="KBO")),COUNT($M$3:M16)+1,"")
A18: 林張子俊 | B18: =IFERROR(INDEX(總表!$B:$B,MATCH($A18,總表!$A:$A,0)),"") -> 旅美 | C18: =IFERROR(INDEX(總表!$G:$G,MATCH($A18,總表!$A:$A,0)),"") -> RK | D18: =IFERROR(INDEX(總表!$C:$C,MATCH($A18,總表!$A:$A,0)),"") -> 投手 | E18: =IFERROR(INDEX(總表!$F:$F,MATCH($A18,總表!$A:$A,0)),"") -> 密爾瓦基釀酒人 | F18: NO | I18: =IF($A18="投手",1,IF($D18="投手",2,IF($A18="野手",3,IF(OR($D18="野手",$D18="內野手",$D18="外野手",$D18="捕手"),4,99)))) -> 2 | J18: {=IF($B18="旅美",1,IF($B18="旅日",2,IF($B18="旅韓",3,IF($B18="台裔",4,IF($B18<>"",5,99)))))} -> 1 | K18: {=IF($C18="MLB",1,IF($C18="3A",2,IF($C18="2A",3,IF(OR($C18="A+",$C18="高A"),4,IF($C18="1A",5,IF(OR($C18="RK",$C18="Rookie"),6,IF($C18="日職一軍",7,IF($C18="日職二軍",8,IF(OR($C18="韓職一軍",$C18="KBO"),9,IF($C18<>"",10,99))))))))))} -> 6 | L18: =IF(AND($D18="投手",LEFT($F18,3)="YES",OR($C18="MLB",$C18="3A",$C18="2A",$C18="日職一軍",$C18="韓職一軍",$C18="KBO")),COUNT($L$3:L17)+1,"") | M18: =IF(AND($D18<>"投手",$D18<>"",LEFT($F18,3)="YES",OR($C18="MLB",$C18="3A",$C18="2A",$C18="日職一軍",$C18="韓職一軍",$C18="KBO")),COUNT($M$3:M17)+1,"")
A19: 林鉑濬 | B19: =IFERROR(INDEX(總表!$B:$B,MATCH($A19,總表!$A:$A,0)),"") -> 旅美 | C19: =IFERROR(INDEX(總表!$G:$G,MATCH($A19,總表!$A:$A,0)),"") -> RK | D19: =IFERROR(INDEX(總表!$C:$C,MATCH($A19,總表!$A:$A,0)),"") -> 投手 | E19: =IFERROR(INDEX(總表!$F:$F,MATCH($A19,總表!$A:$A,0)),"") -> 西雅圖水手 | F19: NO | I19: =IF($A19="投手",1,IF($D19="投手",2,IF($A19="野手",3,IF(OR($D19="野手",$D19="內野手",$D19="外野手",$D19="捕手"),4,99)))) -> 2 | J19: {=IF($B19="旅美",1,IF($B19="旅日",2,IF($B19="旅韓",3,IF($B19="台裔",4,IF($B19<>"",5,99)))))} -> 1 | K19: {=IF($C19="MLB",1,IF($C19="3A",2,IF($C19="2A",3,IF(OR($C19="A+",$C19="高A"),4,IF($C19="1A",5,IF(OR($C19="RK",$C19="Rookie"),6,IF($C19="日職一軍",7,IF($C19="日職二軍",8,IF(OR($C19="韓職一軍",$C19="KBO"),9,IF($C19<>"",10,99))))))))))} -> 6 | L19: =IF(AND($D19="投手",LEFT($F19,3)="YES",OR($C19="MLB",$C19="3A",$C19="2A",$C19="日職一軍",$C19="韓職一軍",$C19="KBO")),COUNT($L$3:L18)+1,"") | M19: =IF(AND($D19<>"投手",$D19<>"",LEFT($F19,3)="YES",OR($C19="MLB",$C19="3A",$C19="2A",$C19="日職一軍",$C19="韓職一軍",$C19="KBO")),COUNT($M$3:M18)+1,"")
A20: 陽念希 | B20: =IFERROR(INDEX(總表!$B:$B,MATCH($A20,總表!$A:$A,0)),"") -> 旅美 | C20: =IFERROR(INDEX(總表!$G:$G,MATCH($A20,總表!$A:$A,0)),"") -> RK | D20: =IFERROR(INDEX(總表!$C:$C,MATCH($A20,總表!$A:$A,0)),"") -> 投手 | E20: =IFERROR(INDEX(總表!$F:$F,MATCH($A20,總表!$A:$A,0)),"") -> 舊金山巨人 | F20: NO | I20: =IF($A20="投手",1,IF($D20="投手",2,IF($A20="野手",3,IF(OR($D20="野手",$D20="內野手",$D20="外野手",$D20="捕手"),4,99)))) -> 2 | J20: {=IF($B20="旅美",1,IF($B20="旅日",2,IF($B20="旅韓",3,IF($B20="台裔",4,IF($B20<>"",5,99)))))} -> 1 | K20: {=IF($C20="MLB",1,IF($C20="3A",2,IF($C20="2A",3,IF(OR($C20="A+",$C20="高A"),4,IF($C20="1A",5,IF(OR($C20="RK",$C20="Rookie"),6,IF($C20="日職一軍",7,IF($C20="日職二軍",8,IF(OR($C20="韓職一軍",$C20="KBO"),9,IF($C20<>"",10,99))))))))))} -> 6 | L20: =IF(AND($D20="投手",LEFT($F20,3)="YES",OR($C20="MLB",$C20="3A",$C20="2A",$C20="日職一軍",$C20="韓職一軍",$C20="KBO")),COUNT($L$3:L19)+1,"") | M20: =IF(AND($D20<>"投手",$D20<>"",LEFT($F20,3)="YES",OR($C20="MLB",$C20="3A",$C20="2A",$C20="日職一軍",$C20="韓職一軍",$C20="KBO")),COUNT($M$3:M19)+1,"")
A21: 蘇嵐鴻 | B21: =IFERROR(INDEX(總表!$B:$B,MATCH($A21,總表!$A:$A,0)),"") -> 旅美 | C21: =IFERROR(INDEX(總表!$G:$G,MATCH($A21,總表!$A:$A,0)),"") -> RK | D21: =IFERROR(INDEX(總表!$C:$C,MATCH($A21,總表!$A:$A,0)),"") -> 投手 | E21: =IFERROR(INDEX(總表!$F:$F,MATCH($A21,總表!$A:$A,0)),"") -> 聖地牙哥教士 | F21: NO | I21: =IF($A21="投手",1,IF($D21="投手",2,IF($A21="野手",3,IF(OR($D21="野手",$D21="內野手",$D21="外野手",$D21="捕手"),4,99)))) -> 2 | J21: {=IF($B21="旅美",1,IF($B21="旅日",2,IF($B21="旅韓",3,IF($B21="台裔",4,IF($B21<>"",5,99)))))} -> 1 | K21: {=IF($C21="MLB",1,IF($C21="3A",2,IF($C21="2A",3,IF(OR($C21="A+",$C21="高A"),4,IF($C21="1A",5,IF(OR($C21="RK",$C21="Rookie"),6,IF($C21="日職一軍",7,IF($C21="日職二軍",8,IF(OR($C21="韓職一軍",$C21="KBO"),9,IF($C21<>"",10,99))))))))))} -> 6 | L21: =IF(AND($D21="投手",LEFT($F21,3)="YES",OR($C21="MLB",$C21="3A",$C21="2A",$C21="日職一軍",$C21="韓職一軍",$C21="KBO")),COUNT($L$3:L20)+1,"") | M21: =IF(AND($D21<>"投手",$D21<>"",LEFT($F21,3)="YES",OR($C21="MLB",$C21="3A",$C21="2A",$C21="日職一軍",$C21="韓職一軍",$C21="KBO")),COUNT($M$3:M20)+1,"")
A22: 宋家豪 | B22: =IFERROR(INDEX(總表!$B:$B,MATCH($A22,總表!$A:$A,0)),"") -> 旅日 | C22: =IFERROR(INDEX(總表!$G:$G,MATCH($A22,總表!$A:$A,0)),"") -> 日職一軍 | D22: =IFERROR(INDEX(總表!$C:$C,MATCH($A22,總表!$A:$A,0)),"") -> 投手 | E22: =IFERROR(INDEX(總表!$F:$F,MATCH($A22,總表!$A:$A,0)),"") -> 東北樂天金鷲 | F22: NO | I22: =IF($A22="投手",1,IF($D22="投手",2,IF($A22="野手",3,IF(OR($D22="野手",$D22="內野手",$D22="外野手",$D22="捕手"),4,99)))) -> 2 | J22: {=IF($B22="旅美",1,IF($B22="旅日",2,IF($B22="旅韓",3,IF($B22="台裔",4,IF($B22<>"",5,99)))))} -> 2 | K22: {=IF($C22="MLB",1,IF($C22="3A",2,IF($C22="2A",3,IF(OR($C22="A+",$C22="高A"),4,IF($C22="1A",5,IF(OR($C22="RK",$C22="Rookie"),6,IF($C22="日職一軍",7,IF($C22="日職二軍",8,IF(OR($C22="韓職一軍",$C22="KBO"),9,IF($C22<>"",10,99))))))))))} -> 7 | L22: =IF(AND($D22="投手",LEFT($F22,3)="YES",OR($C22="MLB",$C22="3A",$C22="2A",$C22="日職一軍",$C22="韓職一軍",$C22="KBO")),COUNT($L$3:L21)+1,"") | M22: =IF(AND($D22<>"投手",$D22<>"",LEFT($F22,3)="YES",OR($C22="MLB",$C22="3A",$C22="2A",$C22="日職一軍",$C22="韓職一軍",$C22="KBO")),COUNT($M$3:M21)+1,"")
A23: 古林睿煬 | B23: =IFERROR(INDEX(總表!$B:$B,MATCH($A23,總表!$A:$A,0)),"") -> 旅日 | C23: =IFERROR(INDEX(總表!$G:$G,MATCH($A23,總表!$A:$A,0)),"") -> 日職二軍 | D23: =IFERROR(INDEX(總表!$C:$C,MATCH($A23,總表!$A:$A,0)),"") -> 投手 | E23: =IFERROR(INDEX(總表!$F:$F,MATCH($A23,總表!$A:$A,0)),"") -> 北海道日本火腿鬥士 | F23: NO | I23: =IF($A23="投手",1,IF($D23="投手",2,IF($A23="野手",3,IF(OR($D23="野手",$D23="內野手",$D23="外野手",$D23="捕手"),4,99)))) -> 2 | J23: {=IF($B23="旅美",1,IF($B23="旅日",2,IF($B23="旅韓",3,IF($B23="台裔",4,IF($B23<>"",5,99)))))} -> 2 | K23: {=IF($C23="MLB",1,IF($C23="3A",2,IF($C23="2A",3,IF(OR($C23="A+",$C23="高A"),4,IF($C23="1A",5,IF(OR($C23="RK",$C23="Rookie"),6,IF($C23="日職一軍",7,IF($C23="日職二軍",8,IF(OR($C23="韓職一軍",$C23="KBO"),9,IF($C23<>"",10,99))))))))))} -> 8 | L23: =IF(AND($D23="投手",LEFT($F23,3)="YES",OR($C23="MLB",$C23="3A",$C23="2A",$C23="日職一軍",$C23="韓職一軍",$C23="KBO")),COUNT($L$3:L22)+1,"") | M23: =IF(AND($D23<>"投手",$D23<>"",LEFT($F23,3)="YES",OR($C23="MLB",$C23="3A",$C23="2A",$C23="日職一軍",$C23="韓職一軍",$C23="KBO")),COUNT($M$3:M22)+1,"")
A24: 孫易磊 | B24: =IFERROR(INDEX(總表!$B:$B,MATCH($A24,總表!$A:$A,0)),"") -> 旅日 | C24: =IFERROR(INDEX(總表!$G:$G,MATCH($A24,總表!$A:$A,0)),"") -> 日職二軍 | D24: =IFERROR(INDEX(總表!$C:$C,MATCH($A24,總表!$A:$A,0)),"") -> 投手 | E24: =IFERROR(INDEX(總表!$F:$F,MATCH($A24,總表!$A:$A,0)),"") -> 北海道日本火腿鬥士 | F24: NO | I24: =IF($A24="投手",1,IF($D24="投手",2,IF($A24="野手",3,IF(OR($D24="野手",$D24="內野手",$D24="外野手",$D24="捕手"),4,99)))) -> 2 | J24: {=IF($B24="旅美",1,IF($B24="旅日",2,IF($B24="旅韓",3,IF($B24="台裔",4,IF($B24<>"",5,99)))))} -> 2 | K24: {=IF($C24="MLB",1,IF($C24="3A",2,IF($C24="2A",3,IF(OR($C24="A+",$C24="高A"),4,IF($C24="1A",5,IF(OR($C24="RK",$C24="Rookie"),6,IF($C24="日職一軍",7,IF($C24="日職二軍",8,IF(OR($C24="韓職一軍",$C24="KBO"),9,IF($C24<>"",10,99))))))))))} -> 8 | L24: =IF(AND($D24="投手",LEFT($F24,3)="YES",OR($C24="MLB",$C24="3A",$C24="2A",$C24="日職一軍",$C24="韓職一軍",$C24="KBO")),COUNT($L$3:L23)+1,"") | M24: =IF(AND($D24<>"投手",$D24<>"",LEFT($F24,3)="YES",OR($C24="MLB",$C24="3A",$C24="2A",$C24="日職一軍",$C24="韓職一軍",$C24="KBO")),COUNT($M$3:M23)+1,"")
... A31: 王彥程 | B31: =IFERROR(INDEX(總表!$B:$B,MATCH($A31,總表!$A:$A,0)),"") -> 旅韓 | C31: =IFERROR(INDEX(總表!$G:$G,MATCH($A31,總表!$A:$A,0)),"") -> 韓職一軍 | D31: =IFERROR(INDEX(總表!$C:$C,MATCH($A31,總表!$A:$A,0)),"") -> 投手 | E31: =IFERROR(INDEX(總表!$F:$F,MATCH($A31,總表!$A:$A,0)),"") -> 韓華鷹 | F31: NO | I31: =IF($A31="投手",1,IF($D31="投手",2,IF($A31="野手",3,IF(OR($D31="野手",$D31="內野手",$D31="外野手",$D31="捕手"),4,99)))) -> 2 | J31: {=IF($B31="旅美",1,IF($B31="旅日",2,IF($B31="旅韓",3,IF($B31="台裔",4,IF($B31<>"",5,99)))))} -> 3 | K31: {=IF($C31="MLB",1,IF($C31="3A",2,IF($C31="2A",3,IF(OR($C31="A+",$C31="高A"),4,IF($C31="1A",5,IF(OR($C31="RK",$C31="Rookie"),6,IF($C31="日職一軍",7,IF($C31="日職二軍",8,IF(OR($C31="韓職一軍",$C31="KBO"),9,IF($C31<>"",10,99))))))))))} -> 9 | L31: =IF(AND($D31="投手",LEFT($F31,3)="YES",OR($C31="MLB",$C31="3A",$C31="2A",$C31="日職一軍",$C31="韓職一軍",$C31="KBO")),COUNT($L$3:L30)+1,"") | M31: =IF(AND($D31<>"投手",$D31<>"",LEFT($F31,3)="YES",OR($C31="MLB",$C31="3A",$C31="2A",$C31="日職一軍",$C31="韓職一軍",$C31="KBO")),COUNT($M$3:M30)+1,"")
A32: 野手 | B32: =IFERROR(INDEX(總表!$B:$B,MATCH($A32,總表!$A:$A,0)),"") | C32: =IFERROR(INDEX(總表!$G:$G,MATCH($A32,總表!$A:$A,0)),"") | D32: =IFERROR(INDEX(總表!$C:$C,MATCH($A32,總表!$A:$A,0)),"") | E32: =IFERROR(INDEX(總表!$F:$F,MATCH($A32,總表!$A:$A,0)),"") | I32: =IF($A32="投手",1,IF($D32="投手",2,IF($A32="野手",3,IF(OR($D32="野手",$D32="內野手",$D32="外野手",$D32="捕手"),4,99)))) -> 3 | J32: {=IF($B32="旅美",1,IF($B32="旅日",2,IF($B32="旅韓",3,IF($B32="台裔",4,IF($B32<>"",5,99)))))} -> 99 | K32: {=IF($C32="MLB",1,IF($C32="3A",2,IF($C32="2A",3,IF(OR($C32="A+",$C32="高A"),4,IF($C32="1A",5,IF(OR($C32="RK",$C32="Rookie"),6,IF($C32="日職一軍",7,IF($C32="日職二軍",8,IF(OR($C32="韓職一軍",$C32="KBO"),9,IF($C32<>"",10,99))))))))))} -> 99 | L32: =IF(AND($D32="投手",LEFT($F32,3)="YES",OR($C32="MLB",$C32="3A",$C32="2A",$C32="日職一軍",$C32="韓職一軍",$C32="KBO")),COUNT($L$3:L31)+1,"") | M32: =IF(AND($D32<>"投手",$D32<>"",LEFT($F32,3)="YES",OR($C32="MLB",$C32="3A",$C32="2A",$C32="日職一軍",$C32="韓職一軍",$C32="KBO")),COUNT($M$3:M31)+1,"")
A33: 李灝宇 | B33: =IFERROR(INDEX(總表!$B:$B,MATCH($A33,總表!$A:$A,0)),"") -> 旅美 | C33: =IFERROR(INDEX(總表!$G:$G,MATCH($A33,總表!$A:$A,0)),"") -> MLB | D33: =IFERROR(INDEX(總表!$C:$C,MATCH($A33,總表!$A:$A,0)),"") -> 野手 | E33: =IFERROR(INDEX(總表!$F:$F,MATCH($A33,總表!$A:$A,0)),"") -> 底特律老虎 | F33: NO(4/22) | I33: =IF($A33="投手",1,IF($D33="投手",2,IF($A33="野手",3,IF(OR($D33="野手",$D33="內野手",$D33="外野手",$D33="捕手"),4,99)))) -> 4 | J33: {=IF($B33="旅美",1,IF($B33="旅日",2,IF($B33="旅韓",3,IF($B33="台裔",4,IF($B33<>"",5,99)))))} -> 1 | K33: {=IF($C33="MLB",1,IF($C33="3A",2,IF($C33="2A",3,IF(OR($C33="A+",$C33="高A"),4,IF($C33="1A",5,IF(OR($C33="RK",$C33="Rookie"),6,IF($C33="日職一軍",7,IF($C33="日職二軍",8,IF(OR($C33="韓職一軍",$C33="KBO"),9,IF($C33<>"",10,99))))))))))} -> 1 | L33: =IF(AND($D33="投手",LEFT($F33,3)="YES",OR($C33="MLB",$C33="3A",$C33="2A",$C33="日職一軍",$C33="韓職一軍",$C33="KBO")),COUNT($L$3:L32)+1,"") | M33: =IF(AND($D33<>"投手",$D33<>"",LEFT($F33,3)="YES",OR($C33="MLB",$C33="3A",$C33="2A",$C33="日職一軍",$C33="韓職一軍",$C33="KBO")),COUNT($M$3:M32)+1,"")
A34: 鄭宗哲 | B34: =IFERROR(INDEX(總表!$B:$B,MATCH($A34,總表!$A:$A,0)),"") -> 旅美 | C34: =IFERROR(INDEX(總表!$G:$G,MATCH($A34,總表!$A:$A,0)),"") -> 3A | D34: =IFERROR(INDEX(總表!$C:$C,MATCH($A34,總表!$A:$A,0)),"") -> 野手 | E34: =IFERROR(INDEX(總表!$F:$F,MATCH($A34,總表!$A:$A,0)),"") -> 波士頓紅襪 | F34: YES | H34: 5AB，1H，3K，AVG.262，OBP.395，SLG.508​ | I34: =IF($A34="投手",1,IF($D34="投手",2,IF($A34="野手",3,IF(OR($D34="野手",$D34="內野手",$D34="外野手",$D34="捕手"),4,99)))) -> 4 | J34: {=IF($B34="旅美",1,IF($B34="旅日",2,IF($B34="旅韓",3,IF($B34="台裔",4,IF($B34<>"",5,99)))))} -> 1 | K34: {=IF($C34="MLB",1,IF($C34="3A",2,IF($C34="2A",3,IF(OR($C34="A+",$C34="高A"),4,IF($C34="1A",5,IF(OR($C34="RK",$C34="Rookie"),6,IF($C34="日職一軍",7,IF($C34="日職二軍",8,IF(OR($C34="韓職一軍",$C34="KBO"),9,IF($C34<>"",10,99))))))))))} -> 2 | L34: =IF(AND($D34="投手",LEFT($F34,3)="YES",OR($C34="MLB",$C34="3A",$C34="2A",$C34="日職一軍",$C34="韓職一軍",$C34="KBO")),COUNT($L$3:L33)+1,"") | M34: =IF(AND($D34<>"投手",$D34<>"",LEFT($F34,3)="YES",OR($C34="MLB",$C34="3A",$C34="2A",$C34="日職一軍",$C34="韓職一軍",$C34="KBO")),COUNT($M$3:M33)+1,"") -> 1
A35: 柯敬賢 | B35: =IFERROR(INDEX(總表!$B:$B,MATCH($A35,總表!$A:$A,0)),"") -> 旅美 | C35: =IFERROR(INDEX(總表!$G:$G,MATCH($A35,總表!$A:$A,0)),"") -> 1A | D35: =IFERROR(INDEX(總表!$C:$C,MATCH($A35,總表!$A:$A,0)),"") -> 外野手 | E35: =IFERROR(INDEX(總表!$F:$F,MATCH($A35,總表!$A:$A,0)),"") -> 洛杉磯道奇 | F35: YES | H35: 3AB，0H，3K，1BB，AVG.346，OBP.469，SLG.654 | I35: =IF($A35="投手",1,IF($D35="投手",2,IF($A35="野手",3,IF(OR($D35="野手",$D35="內野手",$D35="外野手",$D35="捕手"),4,99)))) -> 4 | J35: {=IF($B35="旅美",1,IF($B35="旅日",2,IF($B35="旅韓",3,IF($B35="台裔",4,IF($B35<>"",5,99)))))} -> 1 | K35: {=IF($C35="MLB",1,IF($C35="3A",2,IF($C35="2A",3,IF(OR($C35="A+",$C35="高A"),4,IF($C35="1A",5,IF(OR($C35="RK",$C35="Rookie"),6,IF($C35="日職一軍",7,IF($C35="日職二軍",8,IF(OR($C35="韓職一軍",$C35="KBO"),9,IF($C35<>"",10,99))))))))))} -> 5 | L35: =IF(AND($D35="投手",LEFT($F35,3)="YES",OR($C35="MLB",$C35="3A",$C35="2A",$C35="日職一軍",$C35="韓職一軍",$C35="KBO")),COUNT($L$3:L34)+1,"") | M35: =IF(AND($D35<>"投手",$D35<>"",LEFT($F35,3)="YES",OR($C35="MLB",$C35="3A",$C35="2A",$C35="日職一軍",$C35="韓職一軍",$C35="KBO")),COUNT($M$3:M34)+1,"")
A36: 廖宥霖 | B36: =IFERROR(INDEX(總表!$B:$B,MATCH($A36,總表!$A:$A,0)),"") -> 旅美 | C36: =IFERROR(INDEX(總表!$G:$G,MATCH($A36,總表!$A:$A,0)),"") -> RK | D36: =IFERROR(INDEX(總表!$C:$C,MATCH($A36,總表!$A:$A,0)),"") -> 內野手 | E36: =IFERROR(INDEX(總表!$F:$F,MATCH($A36,總表!$A:$A,0)),"") -> 密爾瓦基釀酒人 | F36: NO | I36: =IF($A36="投手",1,IF($D36="投手",2,IF($A36="野手",3,IF(OR($D36="野手",$D36="內野手",$D36="外野手",$D36="捕手"),4,99)))) -> 4 | J36: {=IF($B36="旅美",1,IF($B36="旅日",2,IF($B36="旅韓",3,IF($B36="台裔",4,IF($B36<>"",5,99)))))} -> 1 | K36: {=IF($C36="MLB",1,IF($C36="3A",2,IF($C36="2A",3,IF(OR($C36="A+",$C36="高A"),4,IF($C36="1A",5,IF(OR($C36="RK",$C36="Rookie"),6,IF($C36="日職一軍",7,IF($C36="日職二軍",8,IF(OR($C36="韓職一軍",$C36="KBO"),9,IF($C36<>"",10,99))))))))))} -> 6 | L36: =IF(AND($D36="投手",LEFT($F36,3)="YES",OR($C36="MLB",$C36="3A",$C36="2A",$C36="日職一軍",$C36="韓職一軍",$C36="KBO")),COUNT($L$3:L35)+1,"") | M36: =IF(AND($D36<>"投手",$D36<>"",LEFT($F36,3)="YES",OR($C36="MLB",$C36="3A",$C36="2A",$C36="日職一軍",$C36="韓職一軍",$C36="KBO")),COUNT($M$3:M35)+1,"")
A37: 林安可 | B37: =IFERROR(INDEX(總表!$B:$B,MATCH($A37,總表!$A:$A,0)),"") -> 旅日 | C37: =IFERROR(INDEX(總表!$G:$G,MATCH($A37,總表!$A:$A,0)),"") -> 日職一軍 | D37: =IFERROR(INDEX(總表!$C:$C,MATCH($A37,總表!$A:$A,0)),"") -> 外野手 | E37: =IFERROR(INDEX(總表!$F:$F,MATCH($A37,總表!$A:$A,0)),"") -> 埼玉西武獅 | F37: NO | I37: =IF($A37="投手",1,IF($D37="投手",2,IF($A37="野手",3,IF(OR($D37="野手",$D37="內野手",$D37="外野手",$D37="捕手"),4,99)))) -> 4 | J37: {=IF($B37="旅美",1,IF($B37="旅日",2,IF($B37="旅韓",3,IF($B37="台裔",4,IF($B37<>"",5,99)))))} -> 2 | K37: {=IF($C37="MLB",1,IF($C37="3A",2,IF($C37="2A",3,IF(OR($C37="A+",$C37="高A"),4,IF($C37="1A",5,IF(OR($C37="RK",$C37="Rookie"),6,IF($C37="日職一軍",7,IF($C37="日職二軍",8,IF(OR($C37="韓職一軍",$C37="KBO"),9,IF($C37<>"",10,99))))))))))} -> 7 | L37: =IF(AND($D37="投手",LEFT($F37,3)="YES",OR($C37="MLB",$C37="3A",$C37="2A",$C37="日職一軍",$C37="韓職一軍",$C37="KBO")),COUNT($L$3:L36)+1,"") | M37: =IF(AND($D37<>"投手",$D37<>"",LEFT($F37,3)="YES",OR($C37="MLB",$C37="3A",$C37="2A",$C37="日職一軍",$C37="韓職一軍",$C37="KBO")),COUNT($M$3:M36)+1,"")
A38: 林冠臣 | B38: =IFERROR(INDEX(總表!$B:$B,MATCH($A38,總表!$A:$A,0)),"") -> 旅日 | C38: =IFERROR(INDEX(總表!$G:$G,MATCH($A38,總表!$A:$A,0)),"") -> 日職二軍 | D38: =IFERROR(INDEX(總表!$C:$C,MATCH($A38,總表!$A:$A,0)),"") -> 野手 | E38: =IFERROR(INDEX(總表!$F:$F,MATCH($A38,總表!$A:$A,0)),"") -> 埼玉西武獅 | F38: NO | I38: =IF($A38="投手",1,IF($D38="投手",2,IF($A38="野手",3,IF(OR($D38="野手",$D38="內野手",$D38="外野手",$D38="捕手"),4,99)))) -> 4 | J38: {=IF($B38="旅美",1,IF($B38="旅日",2,IF($B38="旅韓",3,IF($B38="台裔",4,IF($B38<>"",5,99)))))} -> 2 | K38: {=IF($C38="MLB",1,IF($C38="3A",2,IF($C38="2A",3,IF(OR($C38="A+",$C38="高A"),4,IF($C38="1A",5,IF(OR($C38="RK",$C38="Rookie"),6,IF($C38="日職一軍",7,IF($C38="日職二軍",8,IF(OR($C38="韓職一軍",$C38="KBO"),9,IF($C38<>"",10,99))))))))))} -> 8 | L38: =IF(AND($D38="投手",LEFT($F38,3)="YES",OR($C38="MLB",$C38="3A",$C38="2A",$C38="日職一軍",$C38="韓職一軍",$C38="KBO")),COUNT($L$3:L37)+1,"") | M38: =IF(AND($D38<>"投手",$D38<>"",LEFT($F38,3)="YES",OR($C38="MLB",$C38="3A",$C38="2A",$C38="日職一軍",$C38="韓職一軍",$C38="KBO")),COUNT($M$3:M37)+1,"")
A39: 林家正 | B39: =IFERROR(INDEX(總表!$B:$B,MATCH($A39,總表!$A:$A,0)),"") -> 旅日 | C39: =IFERROR(INDEX(總表!$G:$G,MATCH($A39,總表!$A:$A,0)),"") -> 日職二軍 | D39: =IFERROR(INDEX(總表!$C:$C,MATCH($A39,總表!$A:$A,0)),"") -> 捕手 | E39: =IFERROR(INDEX(總表!$F:$F,MATCH($A39,總表!$A:$A,0)),"") -> 北海道日本火腿鬥士 | F39: NO | I39: =IF($A39="投手",1,IF($D39="投手",2,IF($A39="野手",3,IF(OR($D39="野手",$D39="內野手",$D39="外野手",$D39="捕手"),4,99)))) -> 4 | J39: {=IF($B39="旅美",1,IF($B39="旅日",2,IF($B39="旅韓",3,IF($B39="台裔",4,IF($B39<>"",5,99)))))} -> 2 | K39: {=IF($C39="MLB",1,IF($C39="3A",2,IF($C39="2A",3,IF(OR($C39="A+",$C39="高A"),4,IF($C39="1A",5,IF(OR($C39="RK",$C39="Rookie"),6,IF($C39="日職一軍",7,IF($C39="日職二軍",8,IF(OR($C39="韓職一軍",$C39="KBO"),9,IF($C39<>"",10,99))))))))))} -> 8 | L39: =IF(AND($D39="投手",LEFT($F39,3)="YES",OR($C39="MLB",$C39="3A",$C39="2A",$C39="日職一軍",$C39="韓職一軍",$C39="KBO")),COUNT($L$3:L38)+1,"") | M39: =IF(AND($D39<>"投手",$D39<>"",LEFT($F39,3)="YES",OR($C39="MLB",$C39="3A",$C39="2A",$C39="日職一軍",$C39="韓職一軍",$C39="KBO")),COUNT($M$3:M38)+1,"")
A40: 陽柏翔 | B40: =IFERROR(INDEX(總表!$B:$B,MATCH($A40,總表!$A:$A,0)),"") -> 旅日 | C40: =IFERROR(INDEX(總表!$G:$G,MATCH($A40,總表!$A:$A,0)),"") -> 日職二軍 | D40: =IFERROR(INDEX(總表!$C:$C,MATCH($A40,總表!$A:$A,0)),"") -> 內野手 | E40: =IFERROR(INDEX(總表!$F:$F,MATCH($A40,總表!$A:$A,0)),"") -> 東北樂天金鷲 | F40: NO | I40: =IF($A40="投手",1,IF($D40="投手",2,IF($A40="野手",3,IF(OR($D40="野手",$D40="內野手",$D40="外野手",$D40="捕手"),4,99)))) -> 4 | J40: {=IF($B40="旅美",1,IF($B40="旅日",2,IF($B40="旅韓",3,IF($B40="台裔",4,IF($B40<>"",5,99)))))} -> 2 | K40: {=IF($C40="MLB",1,IF($C40="3A",2,IF($C40="2A",3,IF(OR($C40="A+",$C40="高A"),4,IF($C40="1A",5,IF(OR($C40="RK",$C40="Rookie"),6,IF($C40="日職一軍",7,IF($C40="日職二軍",8,IF(OR($C40="韓職一軍",$C40="KBO"),9,IF($C40<>"",10,99))))))))))} -> 8 | L40: =IF(AND($D40="投手",LEFT($F40,3)="YES",OR($C40="MLB",$C40="3A",$C40="2A",$C40="日職一軍",$C40="韓職一軍",$C40="KBO")),COUNT($L$3:L39)+1,"") | M40: =IF(AND($D40<>"投手",$D40<>"",LEFT($F40,3)="YES",OR($C40="MLB",$C40="3A",$C40="2A",$C40="日職一軍",$C40="韓職一軍",$C40="KBO")),COUNT($M$3:M39)+1,"")
A41: Corbin Carroll | B41: =IFERROR(INDEX(總表!$B:$B,MATCH($A41,總表!$A:$A,0)),"") -> 台裔 | C41: =IFERROR(INDEX(總表!$G:$G,MATCH($A41,總表!$A:$A,0)),"") -> MLB | D41: =IFERROR(INDEX(總表!$C:$C,MATCH($A41,總表!$A:$A,0)),"") -> 外野手 | E41: =IFERROR(INDEX(總表!$F:$F,MATCH($A41,總表!$A:$A,0)),"") -> 亞歷桑納響尾蛇 | F41: YES | H41: 4AB，0H，1K，AVG.296，OBP.396，SLG.580 | I41: =IF($A41="投手",1,IF($D41="投手",2,IF($A41="野手",3,IF(OR($D41="野手",$D41="內野手",$D41="外野手",$D41="捕手"),4,99)))) -> 4 | J41: {=IF($B41="旅美",1,IF($B41="旅日",2,IF($B41="旅韓",3,IF($B41="台裔",4,IF($B41<>"",5,99)))))} -> 4 | K41: {=IF($C41="MLB",1,IF($C41="3A",2,IF($C41="2A",3,IF(OR($C41="A+",$C41="高A"),4,IF($C41="1A",5,IF(OR($C41="RK",$C41="Rookie"),6,IF($C41="日職一軍",7,IF($C41="日職二軍",8,IF(OR($C41="韓職一軍",$C41="KBO"),9,IF($C41<>"",10,99))))))))))} -> 1 | L41: =IF(AND($D41="投手",LEFT($F41,3)="YES",OR($C41="MLB",$C41="3A",$C41="2A",$C41="日職一軍",$C41="韓職一軍",$C41="KBO")),COUNT($L$3:L40)+1,"") | M41: =IF(AND($D41<>"投手",$D41<>"",LEFT($F41,3)="YES",OR($C41="MLB",$C41="3A",$C41="2A",$C41="日職一軍",$C41="韓職一軍",$C41="KBO")),COUNT($M$3:M40)+1,"") -> 2
A42: Jonathon Long | B42: =IFERROR(INDEX(總表!$B:$B,MATCH($A42,總表!$A:$A,0)),"") -> 台裔 | C42: =IFERROR(INDEX(總表!$G:$G,MATCH($A42,總表!$A:$A,0)),"") -> 3A | D42: =IFERROR(INDEX(總表!$C:$C,MATCH($A42,總表!$A:$A,0)),"") -> 內野手 | E42: =IFERROR(INDEX(總表!$F:$F,MATCH($A42,總表!$A:$A,0)),"") -> 芝加哥小熊 | F42: YES | H42: 4AB，0H，AVG.267，OBP.370，SLG.395 | I42: =IF($A42="投手",1,IF($D42="投手",2,IF($A42="野手",3,IF(OR($D42="野手",$D42="內野手",$D42="外野手",$D42="捕手"),4,99)))) -> 4 | J42: {=IF($B42="旅美",1,IF($B42="旅日",2,IF($B42="旅韓",3,IF($B42="台裔",4,IF($B42<>"",5,99)))))} -> 4 | K42: {=IF($C42="MLB",1,IF($C42="3A",2,IF($C42="2A",3,IF(OR($C42="A+",$C42="高A"),4,IF($C42="1A",5,IF(OR($C42="RK",$C42="Rookie"),6,IF($C42="日職一軍",7,IF($C42="日職二軍",8,IF(OR($C42="韓職一軍",$C42="KBO"),9,IF($C42<>"",10,99))))))))))} -> 2 | L42: =IF(AND($D42="投手",LEFT($F42,3)="YES",OR($C42="MLB",$C42="3A",$C42="2A",$C42="日職一軍",$C42="韓職一軍",$C42="KBO")),COUNT($L$3:L41)+1,"") | M42: =IF(AND($D42<>"投手",$D42<>"",LEFT($F42,3)="YES",OR($C42="MLB",$C42="3A",$C42="2A",$C42="日職一軍",$C42="韓職一軍",$C42="KBO")),COUNT($M$3:M41)+1,"") -> 3
A43: Stuart Fairchild | B43: =IFERROR(INDEX(總表!$B:$B,MATCH($A43,總表!$A:$A,0)),"") -> 台裔 | C43: =IFERROR(INDEX(總表!$G:$G,MATCH($A43,總表!$A:$A,0)),"") -> 3A | D43: =IFERROR(INDEX(總表!$C:$C,MATCH($A43,總表!$A:$A,0)),"") -> 外野手 | E43: =IFERROR(INDEX(總表!$F:$F,MATCH($A43,總表!$A:$A,0)),"") -> 克里夫蘭守護者 | F43: NO | I43: =IF($A43="投手",1,IF($D43="投手",2,IF($A43="野手",3,IF(OR($D43="野手",$D43="內野手",$D43="外野手",$D43="捕手"),4,99)))) -> 4 | J43: {=IF($B43="旅美",1,IF($B43="旅日",2,IF($B43="旅韓",3,IF($B43="台裔",4,IF($B43<>"",5,99)))))} -> 4 | K43: {=IF($C43="MLB",1,IF($C43="3A",2,IF($C43="2A",3,IF(OR($C43="A+",$C43="高A"),4,IF($C43="1A",5,IF(OR($C43="RK",$C43="Rookie"),6,IF($C43="日職一軍",7,IF($C43="日職二軍",8,IF(OR($C43="韓職一軍",$C43="KBO"),9,IF($C43<>"",10,99))))))))))} -> 2 | L43: =IF(AND($D43="投手",LEFT($F43,3)="YES",OR($C43="MLB",$C43="3A",$C43="2A",$C43="日職一軍",$C43="韓職一軍",$C43="KBO")),COUNT($L$3:L42)+1,"") | M43: =IF(AND($D43<>"投手",$D43<>"",LEFT($F43,3)="YES",OR($C43="MLB",$C43="3A",$C43="2A",$C43="日職一軍",$C43="韓職一軍",$C43="KBO")),COUNT($M$3:M42)+1,"")
A44: Tyler Wilson | B44: =IFERROR(INDEX(總表!$B:$B,MATCH($A44,總表!$A:$A,0)),"") -> 台裔 | C44: =IFERROR(INDEX(總表!$G:$G,MATCH($A44,總表!$A:$A,0)),"") -> A+ | D44: =IFERROR(INDEX(總表!$C:$C,MATCH($A44,總表!$A:$A,0)),"") -> 內野手 | E44: =IFERROR(INDEX(總表!$F:$F,MATCH($A44,總表!$A:$A,0)),"") -> 紐約洋基 | F44: YES | H44: 4AB，1H，1RBI，1BB，1SB,AVG.200，OBP.267，SLG長打率.250 | I44: =IF($A44="投手",1,IF($D44="投手",2,IF($A44="野手",3,IF(OR($D44="野手",$D44="內野手",$D44="外野手",$D44="捕手"),4,99)))) -> 4 | J44: {=IF($B44="旅美",1,IF($B44="旅日",2,IF($B44="旅韓",3,IF($B44="台裔",4,IF($B44<>"",5,99)))))} -> 4 | K44: {=IF($C44="MLB",1,IF($C44="3A",2,IF($C44="2A",3,IF(OR($C44="A+",$C44="高A"),4,IF($C44="1A",5,IF(OR($C44="RK",$C44="Rookie"),6,IF($C44="日職一軍",7,IF($C44="日職二軍",8,IF(OR($C44="韓職一軍",$C44="KBO"),9,IF($C44<>"",10,99))))))))))} -> 4 | L44: =IF(AND($D44="投手",LEFT($F44,3)="YES",OR($C44="MLB",$C44="3A",$C44="2A",$C44="日職一軍",$C44="韓職一軍",$C44="KBO")),COUNT($L$3:L43)+1,"") | M44: =IF(AND($D44<>"投手",$D44<>"",LEFT($F44,3)="YES",OR($C44="MLB",$C44="3A",$C44="2A",$C44="日職一軍",$C44="韓職一軍",$C44="KBO")),COUNT($M$3:M43)+1,"")
B45: =IFERROR(INDEX(總表!$B:$B,MATCH($A45,總表!$A:$A,0)),"") | C45: =IFERROR(INDEX(總表!$G:$G,MATCH($A45,總表!$A:$A,0)),"") | D45: =IFERROR(INDEX(總表!$C:$C,MATCH($A45,總表!$A:$A,0)),"") | E45: =IFERROR(INDEX(總表!$F:$F,MATCH($A45,總表!$A:$A,0)),"") | I45: =IF($A45="投手",1,IF($D45="投手",2,IF($A45="野手",3,IF(OR($D45="野手",$D45="內野手",$D45="外野手",$D45="捕手"),4,99)))) -> 99 | J45: =IF($B45="旅美",1,IF($B45="旅日",2,IF($B45="旅韓",3,IF($B45="台裔",4,IF($B45<>"",5,99))))) -> 99 | K45: =IF($C45="MLB",1,IF($C45="3A",2,IF($C45="2A",3,IF(OR($C45="A+",$C45="高A"),4,IF($C45="1A",5,IF(OR($C45="RK",$C45="Rookie"),6,IF($C45="日職一軍",7,IF($C45="日職二軍",8,IF(OR($C45="韓職一軍",$C45="KBO"),9,IF($C45<>"",10,99)))))))))) -> 99 | L45: =IF(AND($D45="投手",LEFT($F45,3)="YES",OR($C45="MLB",$C45="3A",$C45="2A",$C45="日職一軍",$C45="韓職一軍",$C45="KBO")),COUNT($L$3:L44)+1,"") | M45: =IF(AND($D45<>"投手",$D45<>"",LEFT($F45,3)="YES",OR($C45="MLB",$C45="3A",$C45="2A",$C45="日職一軍",$C45="韓職一軍",$C45="KBO")),COUNT($M$3:M44)+1,"") | N45: =IF(AND($D45="投手",$F45="YES",OR($C45="MLB",$C45="一軍",$C45="KBO",$C45="3A",$C45="2A")),COUNT($L$2:L44)+1,"")
B46: =IFERROR(INDEX(總表!$B:$B,MATCH($A46,總表!$A:$A,0)),"") | C46: =IFERROR(INDEX(總表!$G:$G,MATCH($A46,總表!$A:$A,0)),"") | D46: =IFERROR(INDEX(總表!$C:$C,MATCH($A46,總表!$A:$A,0)),"") | E46: =IFERROR(INDEX(總表!$F:$F,MATCH($A46,總表!$A:$A,0)),"") | I46: =IF($A46="投手",1,IF($D46="投手",2,IF($A46="野手",3,IF(OR($D46="野手",$D46="內野手",$D46="外野手",$D46="捕手"),4,99)))) -> 99 | J46: =IF($B46="旅美",1,IF($B46="旅日",2,IF($B46="旅韓",3,IF($B46="台裔",4,IF($B46<>"",5,99))))) -> 99 | K46: =IF($C46="MLB",1,IF($C46="3A",2,IF($C46="2A",3,IF(OR($C46="A+",$C46="高A"),4,IF($C46="1A",5,IF(OR($C46="RK",$C46="Rookie"),6,IF($C46="日職一軍",7,IF($C46="日職二軍",8,IF(OR($C46="韓職一軍",$C46="KBO"),9,IF($C46<>"",10,99)))))))))) -> 99 | L46: =IF(AND($D46="投手",LEFT($F46,3)="YES",OR($C46="MLB",$C46="3A",$C46="2A",$C46="日職一軍",$C46="韓職一軍",$C46="KBO")),COUNT($L$3:L45)+1,"") | M46: =IF(AND($D46<>"投手",$D46<>"",LEFT($F46,3)="YES",OR($C46="MLB",$C46="3A",$C46="2A",$C46="日職一軍",$C46="韓職一軍",$C46="KBO")),COUNT($M$3:M45)+1,"") | N46: =IF(AND($D46="投手",$F46="YES",OR($C46="MLB",$C46="一軍",$C46="KBO",$C46="3A",$C46="2A")),COUNT($N$2:N45)+1,"")
...

Sheet 總表
A1: 球員 | B1: 分類 | C1: 守位 | D1: 國家 | E1: 聯盟 | F1: 球隊 | G1: 層級 | H1: 狀態 | I1: 異動 | J1: 排序_分類 | K1: 排序_層級 | L1: 排序_姓名 | M1: 前次_層級 | N1: 狀態序 | O1: 前次狀態 | P1: IL天數 | Q1: IL已過 | R1: 狀態顯示 | S1: 狀態異動 | T1: 狀態排序 | U1: 事件旗標 | V1: 事件序
A2: 李灝宇 | B2: 旅美 | C2: 野手 | D2: 美國 | E2: MLB | F2: 底特律老虎 | G2: MLB | H2: 現役 | I2: =IF($A2="","",IFERROR(INDEX(異動資料源!$G:$G,MATCH($A2,異動資料源!$A:$A,0)),"")) | J2: =IF(B2="","",IF(B2="旅美",1,IF(B2="旅日",2,IF(B2="旅韓",3,IF(B2="其他",4,IF(B2="台裔",5,99)))))) -> 1 | K2: {=IF(G2="MLB",1,IF(G2="日職一軍",2,IF(G2="韓職一軍",3,IF(G2="3A",4,IF(G2="2A",5,IF(G2="A+",6,IF(G2="1A",7,IF(G2="RK",8,IF(G2="日職二軍",9,99)))))))))} -> 1 | L2: =IF(A2="","",A2) -> 李灝宇 | M2: =IF($A2="","",IFERROR(INDEX(異動資料源!$E:$E,MATCH($A2,異動資料源!$A:$A,0)),"")) -> 1 | N2: =IF(AND($A2<>"",$H2<>"現役"),COUNTIFS($A$2:$A2,"<>",$H$2:$H2,"<>現役"),"") | O2: =IF($A2="","",IFERROR(INDEX(異動資料源!$I:$I,MATCH($A2,異動資料源!$A:$A,0)),"現役")) -> 現役 | R2: =IF($A2="","",IF($H2="現役","現役",IF($P2=10,"⚕ IL("&IF($Q2="","?",$Q2)&"/10)",IF($P2=15,"⚕ IL("&IF($Q2="","?",$Q2)&"/15)",IF($P2=60,"⚕ IL("&IF($Q2="","?",$Q2)&"/60)","⚕ 傷兵"))))) -> 現役 | S2: =IF($A2="","",IFERROR(INDEX(異動資料源!$M:$M,MATCH($A2,異動資料源!$A:$A,0)),"")) | T2: =IF($S2<>"",SUM($U$2:U2),"") | U2: =IF($A2="","",IFERROR(INDEX(異動資料源!$N:$N,MATCH($A2,異動資料源!$A:$A,0)),"")) | V2: =IF($A2="","",IFERROR(INDEX(異動資料源!$O:$O,MATCH($A2,異動資料源!$A:$A,0)),""))
A3: 鄧愷威 | B3: 旅美 | C3: 投手 | D3: 美國 | E3: MLB | F3: 休士頓太空人 | G3: MLB | H3: 現役 | I3: =IF($A3="","",IFERROR(INDEX(異動資料源!$G:$G,MATCH($A3,異動資料源!$A:$A,0)),"")) | J3: =IF(B3="","",IF(B3="旅美",1,IF(B3="旅日",2,IF(B3="旅韓",3,IF(B3="其他",4,IF(B3="台裔",5,99)))))) -> 1 | K3: {=IF(G3="MLB",1,IF(G3="日職一軍",2,IF(G3="韓職一軍",3,IF(G3="3A",4,IF(G3="2A",5,IF(G3="A+",6,IF(G3="1A",7,IF(G3="RK",8,IF(G3="日職二軍",9,99)))))))))} -> 1 | L3: =IF(A3="","",A3) -> 鄧愷威 | M3: =IF($A3="","",IFERROR(INDEX(異動資料源!$E:$E,MATCH($A3,異動資料源!$A:$A,0)),"")) -> 1 | N3: =IF(AND($A3<>"",$H3<>"現役"),COUNTIFS($A$2:$A3,"<>",$H$2:$H3,"<>現役"),"") | O3: =IF($A3="","",IFERROR(INDEX(異動資料源!$I:$I,MATCH($A3,異動資料源!$A:$A,0)),"現役")) -> 現役 | R3: =IF($A3="","",IF($H3="現役","現役",IF($P3=10,"⚕ IL("&IF($Q3="","?",$Q3)&"/10)",IF($P3=15,"⚕ IL("&IF($Q3="","?",$Q3)&"/15)",IF($P3=60,"⚕ IL("&IF($Q3="","?",$Q3)&"/60)","⚕ 傷兵"))))) -> 現役 | S3: =IF($A3="","",IFERROR(INDEX(異動資料源!$M:$M,MATCH($A3,異動資料源!$A:$A,0)),"")) | T3: =IF($S3<>"",SUM($U$2:U3),"") | U3: =IF($A3="","",IFERROR(INDEX(異動資料源!$N:$N,MATCH($A3,異動資料源!$A:$A,0)),"")) | V3: =IF($A3="","",IFERROR(INDEX(異動資料源!$O:$O,MATCH($A3,異動資料源!$A:$A,0)),""))
A4: 林昱珉 | B4: 旅美 | C4: 投手 | D4: 美國 | E4: MiLB | F4: 亞利桑那響尾蛇 | G4: 3A | H4: 現役 | I4: =IF($A4="","",IFERROR(INDEX(異動資料源!$G:$G,MATCH($A4,異動資料源!$A:$A,0)),"")) | J4: =IF(B4="","",IF(B4="旅美",1,IF(B4="旅日",2,IF(B4="旅韓",3,IF(B4="其他",4,IF(B4="台裔",5,99)))))) -> 1 | K4: {=IF(G4="MLB",1,IF(G4="日職一軍",2,IF(G4="韓職一軍",3,IF(G4="3A",4,IF(G4="2A",5,IF(G4="A+",6,IF(G4="1A",7,IF(G4="RK",8,IF(G4="日職二軍",9,99)))))))))} -> 4 | L4: =IF(A4="","",A4) -> 林昱珉 | M4: =IF($A4="","",IFERROR(INDEX(異動資料源!$E:$E,MATCH($A4,異動資料源!$A:$A,0)),"")) -> 4 | N4: =IF(AND($A4<>"",$H4<>"現役"),COUNTIFS($A$2:$A4,"<>",$H$2:$H4,"<>現役"),"") | O4: =IF($A4="","",IFERROR(INDEX(異動資料源!$I:$I,MATCH($A4,異動資料源!$A:$A,0)),"現役")) -> 現役 | R4: =IF($A4="","",IF($H4="現役","現役",IF($P4=10,"⚕ IL("&IF($Q4="","?",$Q4)&"/10)",IF($P4=15,"⚕ IL("&IF($Q4="","?",$Q4)&"/15)",IF($P4=60,"⚕ IL("&IF($Q4="","?",$Q4)&"/60)","⚕ 傷兵"))))) -> 現役 | S4: =IF($A4="","",IFERROR(INDEX(異動資料源!$M:$M,MATCH($A4,異動資料源!$A:$A,0)),"")) | T4: =IF($S4<>"",SUM($U$2:U4),"") | U4: =IF($A4="","",IFERROR(INDEX(異動資料源!$N:$N,MATCH($A4,異動資料源!$A:$A,0)),"")) | V4: =IF($A4="","",IFERROR(INDEX(異動資料源!$O:$O,MATCH($A4,異動資料源!$A:$A,0)),""))
A5: 鄭宗哲 | B5: 旅美 | C5: 野手 | D5: 美國 | E5: MiLB | F5: 波士頓紅襪 | G5: 3A | H5: 現役 | I5: =IF($A5="","",IFERROR(INDEX(異動資料源!$G:$G,MATCH($A5,異動資料源!$A:$A,0)),"")) | J5: =IF(B5="","",IF(B5="旅美",1,IF(B5="旅日",2,IF(B5="旅韓",3,IF(B5="其他",4,IF(B5="台裔",5,99)))))) -> 1 | K5: {=IF(G5="MLB",1,IF(G5="日職一軍",2,IF(G5="韓職一軍",3,IF(G5="3A",4,IF(G5="2A",5,IF(G5="A+",6,IF(G5="1A",7,IF(G5="RK",8,IF(G5="日職二軍",9,99)))))))))} -> 4 | L5: =IF(A5="","",A5) -> 鄭宗哲 | M5: =IF($A5="","",IFERROR(INDEX(異動資料源!$E:$E,MATCH($A5,異動資料源!$A:$A,0)),"")) -> 4 | N5: =IF(AND($A5<>"",$H5<>"現役"),COUNTIFS($A$2:$A5,"<>",$H$2:$H5,"<>現役"),"") | O5: =IF($A5="","",IFERROR(INDEX(異動資料源!$I:$I,MATCH($A5,異動資料源!$A:$A,0)),"現役")) -> 現役 | R5: =IF($A5="","",IF($H5="現役","現役",IF($P5=10,"⚕ IL("&IF($Q5="","?",$Q5)&"/10)",IF($P5=15,"⚕ IL("&IF($Q5="","?",$Q5)&"/15)",IF($P5=60,"⚕ IL("&IF($Q5="","?",$Q5)&"/60)","⚕ 傷兵"))))) -> 現役 | S5: =IF($A5="","",IFERROR(INDEX(異動資料源!$M:$M,MATCH($A5,異動資料源!$A:$A,0)),"")) | T5: =IF($S5<>"",SUM($U$2:U5),"") | U5: =IF($A5="","",IFERROR(INDEX(異動資料源!$N:$N,MATCH($A5,異動資料源!$A:$A,0)),"")) | V5: =IF($A5="","",IFERROR(INDEX(異動資料源!$O:$O,MATCH($A5,異動資料源!$A:$A,0)),""))
A6: 林振瑋 | B6: 旅美 | C6: 投手 | D6: 美國 | E6: MiLB | F6: 聖路易紅雀 | G6: 2A | H6: 現役 | I6: =IF($A6="","",IFERROR(INDEX(異動資料源!$G:$G,MATCH($A6,異動資料源!$A:$A,0)),"")) | J6: =IF(B6="","",IF(B6="旅美",1,IF(B6="旅日",2,IF(B6="旅韓",3,IF(B6="其他",4,IF(B6="台裔",5,99)))))) -> 1 | K6: {=IF(G6="MLB",1,IF(G6="日職一軍",2,IF(G6="韓職一軍",3,IF(G6="3A",4,IF(G6="2A",5,IF(G6="A+",6,IF(G6="1A",7,IF(G6="RK",8,IF(G6="日職二軍",9,99)))))))))} -> 5 | L6: =IF(A6="","",A6) -> 林振瑋 | M6: =IF($A6="","",IFERROR(INDEX(異動資料源!$E:$E,MATCH($A6,異動資料源!$A:$A,0)),"")) -> 5 | N6: =IF(AND($A6<>"",$H6<>"現役"),COUNTIFS($A$2:$A6,"<>",$H$2:$H6,"<>現役"),"") | O6: =IF($A6="","",IFERROR(INDEX(異動資料源!$I:$I,MATCH($A6,異動資料源!$A:$A,0)),"現役")) -> 現役 | R6: =IF($A6="","",IF($H6="現役","現役",IF($P6=10,"⚕ IL("&IF($Q6="","?",$Q6)&"/10)",IF($P6=15,"⚕ IL("&IF($Q6="","?",$Q6)&"/15)",IF($P6=60,"⚕ IL("&IF($Q6="","?",$Q6)&"/60)","⚕ 傷兵"))))) -> 現役 | S6: =IF($A6="","",IFERROR(INDEX(異動資料源!$M:$M,MATCH($A6,異動資料源!$A:$A,0)),"")) | T6: =IF($S6<>"",SUM($U$2:U6),"") | U6: =IF($A6="","",IFERROR(INDEX(異動資料源!$N:$N,MATCH($A6,異動資料源!$A:$A,0)),"")) | V6: =IF($A6="","",IFERROR(INDEX(異動資料源!$O:$O,MATCH($A6,異動資料源!$A:$A,0)),""))
A7: 林維恩 | B7: 旅美 | C7: 投手 | D7: 美國 | E7: MiLB | F7: 奧克蘭運動家 | G7: 2A | H7: 現役 | I7: =IF($A7="","",IFERROR(INDEX(異動資料源!$G:$G,MATCH($A7,異動資料源!$A:$A,0)),"")) | J7: =IF(B7="","",IF(B7="旅美",1,IF(B7="旅日",2,IF(B7="旅韓",3,IF(B7="其他",4,IF(B7="台裔",5,99)))))) -> 1 | K7: {=IF(G7="MLB",1,IF(G7="日職一軍",2,IF(G7="韓職一軍",3,IF(G7="3A",4,IF(G7="2A",5,IF(G7="A+",6,IF(G7="1A",7,IF(G7="RK",8,IF(G7="日職二軍",9,99)))))))))} -> 5 | L7: =IF(A7="","",A7) -> 林維恩 | M7: =IF($A7="","",IFERROR(INDEX(異動資料源!$E:$E,MATCH($A7,異動資料源!$A:$A,0)),"")) -> 5 | N7: =IF(AND($A7<>"",$H7<>"現役"),COUNTIFS($A$2:$A7,"<>",$H$2:$H7,"<>現役"),"") | O7: =IF($A7="","",IFERROR(INDEX(異動資料源!$I:$I,MATCH($A7,異動資料源!$A:$A,0)),"現役")) -> 現役 | R7: =IF($A7="","",IF($H7="現役","現役",IF($P7=10,"⚕ IL("&IF($Q7="","?",$Q7)&"/10)",IF($P7=15,"⚕ IL("&IF($Q7="","?",$Q7)&"/15)",IF($P7=60,"⚕ IL("&IF($Q7="","?",$Q7)&"/60)","⚕ 傷兵"))))) -> 現役 | S7: =IF($A7="","",IFERROR(INDEX(異動資料源!$M:$M,MATCH($A7,異動資料源!$A:$A,0)),"")) | T7: =IF($S7<>"",SUM($U$2:U7),"") | U7: =IF($A7="","",IFERROR(INDEX(異動資料源!$N:$N,MATCH($A7,異動資料源!$A:$A,0)),"")) | V7: =IF($A7="","",IFERROR(INDEX(異動資料源!$O:$O,MATCH($A7,異動資料源!$A:$A,0)),""))
A8: 莊陳仲敖 | B8: 旅美 | C8: 投手 | D8: 美國 | E8: MiLB | F8: 奧克蘭運動家 | G8: 2A | H8: 現役 | I8: =IF($A8="","",IFERROR(INDEX(異動資料源!$G:$G,MATCH($A8,異動資料源!$A:$A,0)),"")) | J8: =IF(B8="","",IF(B8="旅美",1,IF(B8="旅日",2,IF(B8="旅韓",3,IF(B8="其他",4,IF(B8="台裔",5,99)))))) -> 1 | K8: {=IF(G8="MLB",1,IF(G8="日職一軍",2,IF(G8="韓職一軍",3,IF(G8="3A",4,IF(G8="2A",5,IF(G8="A+",6,IF(G8="1A",7,IF(G8="RK",8,IF(G8="日職二軍",9,99)))))))))} -> 5 | L8: =IF(A8="","",A8) -> 莊陳仲敖 | M8: =IF($A8="","",IFERROR(INDEX(異動資料源!$E:$E,MATCH($A8,異動資料源!$A:$A,0)),"")) -> 5 | N8: =IF(AND($A8<>"",$H8<>"現役"),COUNTIFS($A$2:$A8,"<>",$H$2:$H8,"<>現役"),"") | O8: =IF($A8="","",IFERROR(INDEX(異動資料源!$I:$I,MATCH($A8,異動資料源!$A:$A,0)),"現役")) -> 現役 | R8: =IF($A8="","",IF($H8="現役","現役",IF($P8=10,"⚕ IL("&IF($Q8="","?",$Q8)&"/10)",IF($P8=15,"⚕ IL("&IF($Q8="","?",$Q8)&"/15)",IF($P8=60,"⚕ IL("&IF($Q8="","?",$Q8)&"/60)","⚕ 傷兵"))))) -> 現役 | S8: =IF($A8="","",IFERROR(INDEX(異動資料源!$M:$M,MATCH($A8,異動資料源!$A:$A,0)),"")) | T8: =IF($S8<>"",SUM($U$2:U8),"") | U8: =IF($A8="","",IFERROR(INDEX(異動資料源!$N:$N,MATCH($A8,異動資料源!$A:$A,0)),"")) | V8: =IF($A8="","",IFERROR(INDEX(異動資料源!$O:$O,MATCH($A8,異動資料源!$A:$A,0)),""))
A9: 陳柏毓 | B9: 旅美 | C9: 投手 | D9: 美國 | E9: MiLB | F9: 匹茲堡海盜 | G9: 2A | H9: 現役 | I9: =IF($A9="","",IFERROR(INDEX(異動資料源!$G:$G,MATCH($A9,異動資料源!$A:$A,0)),"")) | J9: =IF(B9="","",IF(B9="旅美",1,IF(B9="旅日",2,IF(B9="旅韓",3,IF(B9="其他",4,IF(B9="台裔",5,99)))))) -> 1 | K9: {=IF(G9="MLB",1,IF(G9="日職一軍",2,IF(G9="韓職一軍",3,IF(G9="3A",4,IF(G9="2A",5,IF(G9="A+",6,IF(G9="1A",7,IF(G9="RK",8,IF(G9="日職二軍",9,99)))))))))} -> 5 | L9: =IF(A9="","",A9) -> 陳柏毓 | M9: =IF($A9="","",IFERROR(INDEX(異動資料源!$E:$E,MATCH($A9,異動資料源!$A:$A,0)),"")) -> 5 | N9: =IF(AND($A9<>"",$H9<>"現役"),COUNTIFS($A$2:$A9,"<>",$H$2:$H9,"<>現役"),"") | O9: =IF($A9="","",IFERROR(INDEX(異動資料源!$I:$I,MATCH($A9,異動資料源!$A:$A,0)),"現役")) -> 現役 | R9: =IF($A9="","",IF($H9="現役","現役",IF($P9=10,"⚕ IL("&IF($Q9="","?",$Q9)&"/10)",IF($P9=15,"⚕ IL("&IF($Q9="","?",$Q9)&"/15)",IF($P9=60,"⚕ IL("&IF($Q9="","?",$Q9)&"/60)","⚕ 傷兵"))))) -> 現役 | S9: =IF($A9="","",IFERROR(INDEX(異動資料源!$M:$M,MATCH($A9,異動資料源!$A:$A,0)),"")) | T9: =IF($S9<>"",SUM($U$2:U9),"") | U9: =IF($A9="","",IFERROR(INDEX(異動資料源!$N:$N,MATCH($A9,異動資料源!$A:$A,0)),"")) | V9: =IF($A9="","",IFERROR(INDEX(異動資料源!$O:$O,MATCH($A9,異動資料源!$A:$A,0)),""))
A10: 劉致榮 | B10: 旅美 | C10: 投手 | D10: 美國 | E10: MiLB | F10: 波士頓紅襪 | G10: 2A | H10: 傷兵 | I10: =IF($A10="","",IFERROR(INDEX(異動資料源!$G:$G,MATCH($A10,異動資料源!$A:$A,0)),"")) | J10: =IF(B10="","",IF(B10="旅美",1,IF(B10="旅日",2,IF(B10="旅韓",3,IF(B10="其他",4,IF(B10="台裔",5,99)))))) -> 1 | K10: {=IF(G10="MLB",1,IF(G10="日職一軍",2,IF(G10="韓職一軍",3,IF(G10="3A",4,IF(G10="2A",5,IF(G10="A+",6,IF(G10="1A",7,IF(G10="RK",8,IF(G10="日職二軍",9,99)))))))))} -> 5 | L10: =IF(A10="","",A10) -> 劉致榮 | M10: =IF($A10="","",IFERROR(INDEX(異動資料源!$E:$E,MATCH($A10,異動資料源!$A:$A,0)),"")) -> 5 | N10: =IF(AND($A10<>"",$H10<>"現役"),COUNTIFS($A$2:$A10,"<>",$H$2:$H10,"<>現役"),"") -> 1 | O10: =IF($A10="","",IFERROR(INDEX(異動資料源!$I:$I,MATCH($A10,異動資料源!$A:$A,0)),"現役")) -> 傷兵 | P10: 60 | Q10: 39 | R10: =IF($A10="","",IF($H10="現役","現役",IF($P10=10,"⚕ IL("&IF($Q10="","?",$Q10)&"/10)",IF($P10=15,"⚕ IL("&IF($Q10="","?",$Q10)&"/15)",IF($P10=60,"⚕ IL("&IF($Q10="","?",$Q10)&"/60)","⚕ 傷兵"))))) -> ⚕ IL(39/60) | S10: =IF($A10="","",IFERROR(INDEX(異動資料源!$M:$M,MATCH($A10,異動資料源!$A:$A,0)),"")) -> ⚕ IL(39/60) | T10: =IF($S10<>"",SUM($U$2:U10),"") -> 1 | U10: =IF($A10="","",IFERROR(INDEX(異動資料源!$N:$N,MATCH($A10,異動資料源!$A:$A,0)),"")) -> 1 | V10: =IF($A10="","",IFERROR(INDEX(異動資料源!$O:$O,MATCH($A10,異動資料源!$A:$A,0)),"")) -> 1
A11: 沙子宸 | B11: 旅美 | C11: 投手 | D11: 美國 | E11: MiLB | F11: 奧克蘭運動家 | G11: A+ | H11: 現役 | I11: =IF($A11="","",IFERROR(INDEX(異動資料源!$G:$G,MATCH($A11,異動資料源!$A:$A,0)),"")) | J11: =IF(B11="","",IF(B11="旅美",1,IF(B11="旅日",2,IF(B11="旅韓",3,IF(B11="其他",4,IF(B11="台裔",5,99)))))) -> 1 | K11: {=IF(G11="MLB",1,IF(G11="日職一軍",2,IF(G11="韓職一軍",3,IF(G11="3A",4,IF(G11="2A",5,IF(G11="A+",6,IF(G11="1A",7,IF(G11="RK",8,IF(G11="日職二軍",9,99)))))))))} -> 6 | L11: =IF(A11="","",A11) -> 沙子宸 | M11: =IF($A11="","",IFERROR(INDEX(異動資料源!$E:$E,MATCH($A11,異動資料源!$A:$A,0)),"")) -> 6 | N11: =IF(AND($A11<>"",$H11<>"現役"),COUNTIFS($A$2:$A11,"<>",$H$2:$H11,"<>現役"),"") | O11: =IF($A11="","",IFERROR(INDEX(異動資料源!$I:$I,MATCH($A11,異動資料源!$A:$A,0)),"現役")) -> 現役 | R11: =IF($A11="","",IF($H11="現役","現役",IF($P11=10,"⚕ IL("&IF($Q11="","?",$Q11)&"/10)",IF($P11=15,"⚕ IL("&IF($Q11="","?",$Q11)&"/15)",IF($P11=60,"⚕ IL("&IF($Q11="","?",$Q11)&"/60)","⚕ 傷兵"))))) -> 現役 | S11: =IF($A11="","",IFERROR(INDEX(異動資料源!$M:$M,MATCH($A11,異動資料源!$A:$A,0)),"")) | T11: =IF($S11<>"",SUM($U$2:U11),"") | U11: =IF($A11="","",IFERROR(INDEX(異動資料源!$N:$N,MATCH($A11,異動資料源!$A:$A,0)),"")) | V11: =IF($A11="","",IFERROR(INDEX(異動資料源!$O:$O,MATCH($A11,異動資料源!$A:$A,0)),""))
A12: 張弘稜 | B12: 旅美 | C12: 投手 | D12: 美國 | E12: MiLB | F12: 匹茲堡海盜 | G12: A+ | H12: 現役 | I12: =IF($A12="","",IFERROR(INDEX(異動資料源!$G:$G,MATCH($A12,異動資料源!$A:$A,0)),"")) | J12: =IF(B12="","",IF(B12="旅美",1,IF(B12="旅日",2,IF(B12="旅韓",3,IF(B12="其他",4,IF(B12="台裔",5,99)))))) -> 1 | K12: {=IF(G12="MLB",1,IF(G12="日職一軍",2,IF(G12="韓職一軍",3,IF(G12="3A",4,IF(G12="2A",5,IF(G12="A+",6,IF(G12="1A",7,IF(G12="RK",8,IF(G12="日職二軍",9,99)))))))))} -> 6 | L12: =IF(A12="","",A12) -> 張弘稜 | M12: =IF($A12="","",IFERROR(INDEX(異動資料源!$E:$E,MATCH($A12,異動資料源!$A:$A,0)),"")) -> 6 | N12: =IF(AND($A12<>"",$H12<>"現役"),COUNTIFS($A$2:$A12,"<>",$H$2:$H12,"<>現役"),"") | O12: =IF($A12="","",IFERROR(INDEX(異動資料源!$I:$I,MATCH($A12,異動資料源!$A:$A,0)),"現役")) -> 現役 | R12: =IF($A12="","",IF($H12="現役","現役",IF($P12=10,"⚕ IL("&IF($Q12="","?",$Q12)&"/10)",IF($P12=15,"⚕ IL("&IF($Q12="","?",$Q12)&"/15)",IF($P12=60,"⚕ IL("&IF($Q12="","?",$Q12)&"/60)","⚕ 傷兵"))))) -> 現役 | S12: =IF($A12="","",IFERROR(INDEX(異動資料源!$M:$M,MATCH($A12,異動資料源!$A:$A,0)),"")) | T12: =IF($S12<>"",SUM($U$2:U12),"") | U12: =IF($A12="","",IFERROR(INDEX(異動資料源!$N:$N,MATCH($A12,異動資料源!$A:$A,0)),"")) | V12: =IF($A12="","",IFERROR(INDEX(異動資料源!$O:$O,MATCH($A12,異動資料源!$A:$A,0)),""))
